Workbook
Name csDesignMode: 1
Name TaxTV: 10%
Name TaxXL: 5%
Name upsell: _xlfn.LAMBDA(_xlpm.HIGHER,_xlpm.LOWER,_xlpm.MARKUP, CEILING(CEILING(_xlpm.HIGHER-_xlpm.LOWER, 10000) + (CEILING(_xlpm.HIGHER-_xlpm.LOWER, 10000) * _xlpm.MARKUP), 10000))
Name upsell: _xlfn.LAMBDA(_xlpm.HIGHER,_xlpm.LOWER,_xlpm.MARKUP, CEILING(CEILING(_xlpm.HIGHER-_xlpm.LOWER, 10000) + (CEILING(_xlpm.HIGHER-_xlpm.LOWER, 10000) * _xlpm.MARKUP), 10000))
Name zone_saisie: #REF!,#REF!,#REF!,#REF!,#REF!
Name zone_saisie: #REF!,#REF!,#REF!,#REF!,#REF!
Name zone_saisie: #REF!,#REF!,#REF!,#REF!,#REF!

Sheet 6. Rate Simulation
A2: The Anvaya Beach Resort Bali | H2: Isi besaran discount hanya pada bagian yang berwarna abu-abu Promo tidak harus diisi seluruhnya, sesuaikan dengan kebutuhan hotel (weekend offer & min stay bersifat optional)
A3: RATE STRUCTURE I RATE SIMULASI I format hitung budget Room OCC & Revenue - Santika Indonesia Hotels & Resorts
H6: Additional Disc : | I6: 0.03 | M6: Additional Disc : | N6: 0.08
C7: Online Travel Agent | H7: Brand.com
A8: Rate Structure | B8: Lowest Room Type Category | C8: Generic Promotion | H8: Publish Rate - Non member | M8: MyValue Rate
C9: Staycation Offer | D9: Flexible Staycation Offer | E9: EBO 60 | H9: =C9 -> Staycation Offer | I9: =D9 -> Flexible Staycation Offer | J9: =E9 -> EBO 60 | K9: =F9 -> 0 | L9: =G9 -> 0 | M9: =H9 -> Staycation Offer | N9: =I9 -> Flexible Staycation Offer | O9: =J9 -> EBO 60 | ... Q9: =L9 -> 0
C10: 0.32 | D10: 0.27 | E10: 0.35 | H10: =C10+$I$6 -> 0.35 | I10: =D10+$I$6 -> 0.3 | J10: =E10+$I$6 -> 0.38 | K10: =F10+$I$6 -> 0.03 | L10: =G10+$I$6 -> 0.03 | M10: =C10+$N$6 -> 0.4 | N10: =D10+$N$6 -> 0.35 | O10: =E10+$N$6 -> 0.43 | P10: =F10+$N$6 -> 0.08 | Q10: =G10+$N$6 -> 0.08
A11: Internet Rate / WIG Rate / BAR 1 | B11: ='7. Rate Strategy'!F16 -> 5850000 | C11: =$B11-($B11*C$10) -> 3978000 | D11: =$B11-($B11*D$10) -> 4270500 | E11: =$B11-($B11*E$10) -> 3802500 | F11: =$B11-($B11*F$10) -> 5850000 | G11: =$B11-($B11*G$10) -> 5850000 | H11: =$B11-($B11*H$10) -> 3802500 | I11: =$B11-($B11*I$10) -> 4095000 | J11: =$B11-($B11*J$10) -> 3627000 | ... Q11: =$B11-($B11*Q$10) -> 5382000
A12: Internet Rate / WIG Rate / BAR 2 | B12: ='7. Rate Strategy'!F17 -> 5525000 | C12: =$B12-($B12*C$10) -> 3757000 | D12: =$B12-($B12*D$10) -> 4033250 | E12: =$B12-($B12*E$10) -> 3591250 | F12: =$B12-($B12*F$10) -> 5525000 | G12: =$B12-($B12*G$10) -> 5525000 | H12: =$B12-($B12*H$10) -> 3591250 | I12: =$B12-($B12*I$10) -> 3867500 | J12: =$B12-($B12*J$10) -> 3425500 | ... Q12: =$B12-($B12*Q$10) -> 5083000
A13: Internet Rate / WIG Rate / BAR 3 | B13: ='7. Rate Strategy'!F18 -> 5200000 | C13: =$B13-($B13*C$10) -> 3536000 | D13: =$B13-($B13*D$10) -> 3796000 | E13: =$B13-($B13*E$10) -> 3380000 | F13: =$B13-($B13*F$10) -> 5200000 | G13: =$B13-($B13*G$10) -> 5200000 | H13: =$B13-($B13*H$10) -> 3380000 | I13: =$B13-($B13*I$10) -> 3640000 | J13: =$B13-($B13*J$10) -> 3224000 | ... Q13: =$B13-($B13*Q$10) -> 4784000
A14: Internet Rate / WIG Rate / BAR 4 | B14: ='7. Rate Strategy'!F19 -> 4875000 | C14: =$B14-($B14*C$10) -> 3315000 | D14: =$B14-($B14*D$10) -> 3558750 | E14: =$B14-($B14*E$10) -> 3168750 | F14: =$B14-($B14*F$10) -> 4875000 | G14: =$B14-($B14*G$10) -> 4875000 | H14: =$B14-($B14*H$10) -> 3168750 | I14: =$B14-($B14*I$10) -> 3412500 | J14: =$B14-($B14*J$10) -> 3022500 | ... Q14: =$B14-($B14*Q$10) -> 4485000
A15: Internet Rate / WIG Rate / BAR 5 | B15: ='7. Rate Strategy'!F20 -> 4550000 | C15: =$B15-($B15*C$10) -> 3094000 | D15: =$B15-($B15*D$10) -> 3321500 | E15: =$B15-($B15*E$10) -> 2957500 | F15: =$B15-($B15*F$10) -> 4550000 | G15: =$B15-($B15*G$10) -> 4550000 | H15: =$B15-($B15*H$10) -> 2957500 | I15: =$B15-($B15*I$10) -> 3185000 | J15: =$B15-($B15*J$10) -> 2821000 | ... Q15: =$B15-($B15*Q$10) -> 4186000
A16: Internet Rate / WIG Rate / BAR 6 | B16: ='7. Rate Strategy'!F21 -> 3900000 | C16: =$B16-($B16*C$10) -> 2652000 | D16: =$B16-($B16*D$10) -> 2847000 | E16: =$B16-($B16*E$10) -> 2535000 | F16: =$B16-($B16*F$10) -> 3900000 | G16: =$B16-($B16*G$10) -> 3900000 | H16: =$B16-($B16*H$10) -> 2535000 | I16: =$B16-($B16*I$10) -> 2730000 | J16: =$B16-($B16*J$10) -> 2418000 | ... Q16: =$B16-($B16*Q$10) -> 3588000
A17: Internet Rate / WIG Rate / BAR 7 | B17: ='7. Rate Strategy'!F22 -> 3737500 | C17: =$B17-($B17*C$10) -> 2541500 | D17: =$B17-($B17*D$10) -> 2728375 | E17: =$B17-($B17*E$10) -> 2429375 | F17: =$B17-($B17*F$10) -> 3737500 | G17: =$B17-($B17*G$10) -> 3737500 | H17: =$B17-($B17*H$10) -> 2429375 | I17: =$B17-($B17*I$10) -> 2616250 | J17: =$B17-($B17*J$10) -> 2317250 | ... Q17: =$B17-($B17*Q$10) -> 3438500
A18: Internet Rate / WIG Rate / BAR 8 | C18: =$B18-($B18*C$10) -> 0 | D18: =$B18-($B18*D$10) -> 0 | E18: =$B18-($B18*E$10) -> 0 | F18: =$B18-($B18*F$10) -> 0 | G18: =$B18-($B18*G$10) -> 0 | H18: =$B18-($B18*H$10) -> 0 | I18: =$B18-($B18*I$10) -> 0 | J18: =$B18-($B18*J$10) -> 0 | ... Q18: =$B18-($B18*Q$10) -> 0
A19: Internet Rate / WIG Rate / BAR 9 | C19: =$B19-($B19*C$10) -> 0 | D19: =$B19-($B19*D$10) -> 0 | E19: =$B19-($B19*E$10) -> 0 | F19: =$B19-($B19*F$10) -> 0 | G19: =$B19-($B19*G$10) -> 0 | H19: =$B19-($B19*H$10) -> 0 | I19: =$B19-($B19*I$10) -> 0 | J19: =$B19-($B19*J$10) -> 0 | ... Q19: =$B19-($B19*Q$10) -> 0
A20: Internet Rate / WIG Rate / BAR 10 | C20: =$B20-($B20*C$10) -> 0 | D20: =$B20-($B20*D$10) -> 0 | E20: =$B20-($B20*E$10) -> 0 | F20: =$B20-($B20*F$10) -> 0 | G20: =$B20-($B20*G$10) -> 0 | H20: =$B20-($B20*H$10) -> 0 | I20: =$B20-($B20*I$10) -> 0 | J20: =$B20-($B20*J$10) -> 0 | ... Q20: =$B20-($B20*Q$10) -> 0
A21: Internet Rate / WIG Rate / BAR 11 | C21: =$B21-($B21*C$10) -> 0 | D21: =$B21-($B21*D$10) -> 0 | E21: =$B21-($B21*E$10) -> 0 | F21: =$B21-($B21*F$10) -> 0 | G21: =$B21-($B21*G$10) -> 0 | H21: =$B21-($B21*H$10) -> 0 | I21: =$B21-($B21*I$10) -> 0 | J21: =$B21-($B21*J$10) -> 0 | ... Q21: =$B21-($B21*Q$10) -> 0
A22: Bottom Online BAR Rate | B22: =B17 -> 3737500 | C22: =C17 -> 2541500 | D22: =D17 -> 2728375 | E22: =E17 -> 2429375 | F22: =F17 -> 3737500 | G22: =G17 -> 3737500 | H22: =H17 -> 2429375 | I22: =I17 -> 2616250 | ... P22: =P17 -> 3438500 | Q22: =$B20-($B20*Q$10) -> 0
C24: Corporate Promotion
B25: Harga ini adalah harga kontrak 1 thn | C25: Shourlder | D25: High | E25: Peak | F25: Normal
C26: -500000 | D26: -500000 | E26: -700000
A27: Corporate New/NCR | B27: ='7. Rate Strategy'!F32 -> 2150000 | C27: =$B27-C$26 -> 2650000 | D27: =$B27-D$26 -> 2650000 | E27: =$B27-E$26 -> 2850000 | F27: =$B27-($B27*F$26) -> 2150000 | H27: BAR akan menyesuaikan dengan Season. BAR 1-4 akan di apply pada periode High dan Peak Season
A28: Corporate Productive | B28: ='7. Rate Strategy'!F33 -> 2100000 | C28: =$B$28-C$26 -> 2600000 | D28: =$B$28-D$26 -> 2600000 | E28: =$B$28-E$26 -> 2800000 | F28: =$B28-($B28*F$26) -> 2100000
A29: Corporate Super Productive/NKA | B29: ='7. Rate Strategy'!F34 -> 2050000 | C29: =$B$29-C$26 -> 2550000 | D29: =$B$29-D$26 -> 2550000 | E29: =$B$29-E$26 -> 2750000 | F29: =$B29-($B29*F$26) -> 2050000
A30: KKG - DLK | C30: =$B30-($B30*C$26) -> 0 | D30: =$B30-($B30*D$26) -> 0 | E30: =$B30-($B30*E$26) -> 0 | F30: =$B30-($B30*F$26) -> 0
A31: Corporate Preffered | C31: =$B31-($B31*C$26) -> 0 | D31: =$B31-($B31*D$26) -> 0 | E31: =$B31-($B31*E$26) -> 0 | F31: =$B31-($B31*F$26) -> 0
A32: Corporate With Inclusion 1 | C32: Harga Corporate include (laundry, transport, etc ) namun bukan package untuk umum
A33: Corporate With Inclusion 2
A34: Corporate With Inclusion 3
A35: Corporate With Inclusion 4
A36: Corporate With Inclusion 5
A38: Government New | B38: =B27 -> 2150000
A39: Government Productive | B39: =B28 -> 2100000
A40: Government Super Productive | B40: 0
A41: Government Preferred 1
A42: Government Preferred 2
A43: Government Preferred 3
A44: Government with Inclusion 1 | C44: Harga Govt include (laundry, transport, etc ) namun bukan package untuk umum
A45: Government with Inclusion 2
...

Sheet 7. Rate Strategy
B1: The Anvaya Beach Resort Bali
B2: RATE STRUCTURE I RATE STRATEGY I budget format Santika Indonesia Hotels & Resorts
Y3: Rate
B4: Hotel Unit | C4: : | X4: B'fast Rate | Y4: 0 | Z4: 280000
B5: Updated | C5: : | X5: Double Occ | Y5: 0 | Z5: 1.8
X6: spc. Arrangement | Y6: benefit 1 | Z6: benefit 2 | AA6: benefit 3 | AB6: benefit 4 | AC6: benefit 5 | AD6: benefit 6 | AE6: benefit 7
Y7: 0 | Z7: 0 | AA7: 0 | AB7: 0 | AC7: 0 | AD7: 0 | AG7: bisa di input sama
B9: 2024 | E9: RATE STRUCTURE TO BUDGET ACHIEVEMENT | X9: BUSINESS MIX TO BUDGET ACHIEVEMENT | AR9: REVENUE ACHIEVEMENT ( nett )
E10: R. Type | F10: Deluxe Room | G10: Deluxe Pool Access | H10: Premiere Room | I10: Premiere Lagoon Access | J10: Family Premiere | K10: Deluxe Suite | L10: Premiere Suite | M10: The Anvaya Suite No Pool | N10: The Anvaya Suite Whirl Pool | O10: Beach Front Private Suite | P10: Anvaya Residence | Q10: The Anvaya Suite with Pool | R10: The Anvaya Villa | X10: Rate Segment Mix | Z10: Budget Market Segment Mix | AA10: Last Year Market Segment Mix | AB10: R. Type | AC10: =F10 -> Deluxe Room | AD10: =G10 -> Deluxe Pool Access | AE10: =H10 -> Premiere Room | AF10: =I10 -> Premiere Lagoon Access | AG10: =J10 -> Family Premiere | AH10: =K10 -> Deluxe Suite | AI10: =L10 -> Premiere Suite | AJ10: =M10 -> The Anvaya Suite No Pool | AK10: =O10 -> Beach Front Private Suite | AL10: =N10 -> The Anvaya Suite Whirl Pool | AM10: =P10 -> Anvaya Residence | AN10: =Q10 -> The Anvaya Suite with Pool | AO10: =R10 -> The Anvaya Villa | AR10: =AC10 -> Deluxe Room | AS10: =AD10 -> Deluxe Pool Access | AT10: =AE10 -> Premiere Room | AU10: =AF10 -> Premiere Lagoon Access | AV10: =AG10 -> Family Premiere | AW10: =AH10 -> Deluxe Suite | AX10: =AI10 -> Premiere Suite | AY10: =AJ10 -> The Anvaya Suite No Pool | ... BD10: =AO10 -> The Anvaya Villa | BE10: Total Revenue
E11: Publish | F11: =CEILING(F13+(F13*F12),100000) -> 6500000 | G11: =CEILING(G13+(G13*G12),100000) -> 7000000 | H11: =CEILING(H13+(H13*H12),100000) -> 7400000 | I11: =CEILING(I13+(I13*I12),100000) -> 9200000 | J11: =CEILING(J13+(J13*J12),100000) -> 11100000 | K11: =CEILING(K13+(K13*K12),100000) -> 13800000 | L11: =CEILING(L13+(L13*L12),100000) -> 14700000 | M11: =CEILING(M13+(M13*M12),100000) -> 18400000 | ... R11: =CEILING(R13+(R13*R12),100000) -> 56100000 | AB11: R. Avail | AC11: =139*365 -> 50735 | AD11: =21*365 -> 7665 | AE11: =264*365 -> 96360 | AF11: =30*365 -> 10950 | AG11: =5*365 -> 1825 | AH11: =5*365 -> 1825 | AI11: =9*365 -> 3285 | AJ11: =4*365 -> 1460 | AK11: =8*365 -> 2920 | AL11: =4*365 -> 1460 | AM11: =1*365 -> 365 | AN11: =2*365 -> 730 | AO11: =1*365 -> 365 | AP11: =SUM(AC11:AO11) -> 179945 | AT11: incl. benefit 1 | AU11: incl. benefit 2 | AV11: incl. benefit 3 | AW11: incl. benefit 4 | AX11: incl. benefit 5 | AY11: incl. benefit 5 | AZ11: incl. benefit 5 | BA11: incl. benefit 5 | BB11: incl. benefit 5 | BC11: incl. benefit 5 | BD11: incl. benefit 5
F12: 0.12 | G12: 0.12 | H12: 0.12 | I12: 0.12 | J12: 0.12 | K12: 0.1 | L12: 0.1 | M12: 0.1 | N12: 0.1 | O12: 0.1 | P12: 0.06 | Q12: 0.1 | R12: 0.06
E13: 2025 | F13: 5800000 | G13: 6250000 | H13: 6550000 | I13: 8200000 | J13: 9900000 | K13: 12500000 | L13: 13300000 | M13: 16650000 | N13: 18100000 | O13: 18800000 | P13: 19050000 | Q13: 24100000 | R13: 52900000
AB14: Share | AC14: 0.36 | AD14: 0.05 | AE14: 0.463 | AF14: 0.08 | AG14: 0.01 | AH14: 0.01 | AI14: 0.005 | AJ14: 0.005 | AK14: 0.004 | AL14: 0.01 | AM14: 0.001 | AN14: 0.001 | AO14: 0.001 | AP14: =SUM(AC14:AO14) -> 1
AB15: R. Sold | AC15: =AC14*$V$17 -> 51864.154 | AD15: =AD14*$V$17 -> 7203.3547 | AE15: =AE14*$V$17 -> 66703.065 | AF15: =AF14*$V$17 -> 11525.368 | AG15: =AG14*$V$17 -> 1440.6709 | AH15: =AH14*$V$17 -> 1440.6709 | AI15: =AI14*$V$17 -> 720.33547 | AJ15: =AJ14*$V$17 -> 720.33547 | ... AO15: =AO14*$V$17 -> 144.06709 | AP15: =SUM(AC15:AO15) -> 144067.09 | BF15: Total per segment | BH15: budget per segment
B16: Internet Rate / WIG Rate / BAR 1 | E16: 0.1 | F16: =IF(COUNTA($E16),F$11-(F$11*$E16),0) -> 5850000 | G16: =IF(COUNTA($E16),G$11-(G$11*$E16),0) -> 6300000 | H16: =IF(COUNTA($E16),H$11-(H$11*$E16),0) -> 6660000 | I16: =IF(COUNTA($E16),I$11-(I$11*$E16),0) -> 8280000 | J16: =IF(COUNTA($E16),J$11-(J$11*$E16),0) -> 9990000 | K16: =IF(COUNTA($E16),K$11-(K$11*$E16),0) -> 12420000 | L16: =IF(COUNTA($E16),L$11-(L$11*$E16),0) -> 13230000 | M16: =IF(COUNTA($E16),M$11-(M$11*$E16),0) -> 16560000 | ... R16: =IF(COUNTA($E16),R$11-(R$11*$E16),0) -> 50490000 | T16: BUDGET | U16: : | V16: =B9 -> 2024 | X16: =SUM(Y16:Y30) -> 0.37 | Y16: 0 | Z16: 0.46162285 | AA16: 0.34063599 | AC16: =$AC$15*Y16 -> 0 | AD16: =$AD$15*Y16 -> 0 | AE16: =$AE$15*Y16 -> 0 | AF16: =$AF$15*Y16 -> 0 | AG16: =$AG$15*Y16 -> 0 | AH16: =$AH$15*Y16 -> 0 | AI16: =$AI$15*Y16 -> 0 | AJ16: =$AJ$15*Y16 -> 0 | AK16: =$AK$15*Y16 -> 0 | AL16: =$AL$15*Y16 -> 0 | AM16: =$AM$15*Y16 -> 0 | AN16: =$AN$15*Y16 -> 0 | AO16: =$AO$15*Y16 -> 0 | AP16: =SUM(AC16:AO16) -> 0 | AR16: =IF(AC16=0,0,((F16*AC16)-($Y$4*$Y$5*AC16)-Y$7*AC16)/1.21) -> 0 | AT16: =IF(AE16=0,0,((H16*AE16)-($Y$4*$Y$5*AE16)-AA$7*AE16)/1.21) -> 0 | AU16: =IF(AF16=0,0,((I16*AF16)-($Y$4*$Y$5*AF16)-AB$7*AF16)/1.21) -> 0 | AV16: =IF(AG16=0,0,((J16*AG16)-($Y$4*$Y$5*AG16)-AC$7*AG16)/1.21) -> 0 | AW16: =IF(AH16=0,0,((K16*AH16)-($Y$4*$Y$5*AH16)-AD$7*AH16)/1.21) -> 0 | AX16: =IF(AI16=0,0,((L16*AI16)-($Y$4*$Y$5*AI16)-AE$7*AI16)/1.21) -> 0 | AY16: =IF(AJ16=0,0,((M16*AJ16)-($Y$4*$Y$5*AJ16)-AF$7*AJ16)/1.21) -> 0 | AZ16: =IF(AK16=0,0,((O16*AK16)-($Z$4*$Z$5*AK16)-AD7*AK16)/1.21) -> 0 | BA16: =IF(AL16=0,0,((N16*AL16)-($Y$4*$Y$5*AL16)-AH$7*AL16)/1.21) -> 0 | BB16: =IF(AM16=0,0,((P16*AM16)-($Y$4*$Y$5*AM16)-AI$7*AM16)/1.21) -> 0 | BC16: =IF(AN16=0,0,((Q16*AN16)-($Y$4*$Y$5*AN16)-AJ$7*AN16)/1.21) -> 0 | BD16: =IF(AO16=0,0,((R16*AO16)-($Y$4*$Y$5*AO16)-AK$7*AO16)/1.21) -> 0 | BE16: =SUM(AR16:BD16) -> 0 | BF16: =BK20 -> 0 | BG16: FIT + Online | BH16: 100286064118 | BI16: =SUM(BE16:BE30) -> 1.3804436e+11 | BJ16: Online Share
B17: Internet Rate / WIG Rate / BAR 2 | E17: 0.15 | F17: =IF(COUNTA($E17),F$11-(F$11*$E17),0) -> 5525000 | G17: =IF(COUNTA($E17),G$11-(G$11*$E17),0) -> 5950000 | H17: =IF(COUNTA($E17),H$11-(H$11*$E17),0) -> 6290000 | I17: =IF(COUNTA($E17),I$11-(I$11*$E17),0) -> 7820000 | J17: =IF(COUNTA($E17),J$11-(J$11*$E17),0) -> 9435000 | K17: =IF(COUNTA($E17),K$11-(K$11*$E17),0) -> 11730000 | L17: =IF(COUNTA($E17),L$11-(L$11*$E17),0) -> 12495000 | M17: =IF(COUNTA($E17),M$11-(M$11*$E17),0) -> 15640000 | ... R17: =IF(COUNTA($E17),R$11-(R$11*$E17),0) -> 47685000 | T17: Room Sold | U17: : | V17: 144067.09 | Y17: 0 | AC17: =$AC$15*Y17 -> 0 | AD17: =$AD$15*Y17 -> 0 | AE17: =$AE$15*Y17 -> 0 | AF17: =$AF$15*Y17 -> 0 | AG17: =$AG$15*Y17 -> 0 | AH17: =$AH$15*Y17 -> 0 | AI17: =$AI$15*Y17 -> 0 | AJ17: =$AJ$15*Y17 -> 0 | AK17: =$AK$15*Y17 -> 0 | AL17: =$AL$15*Y17 -> 0 | AM17: =$AM$15*Y17 -> 0 | AN17: =$AN$15*Y17 -> 0 | AO17: =$AO$15*Y17 -> 0 | AP17: =SUM(AC17:AO17) -> 0 | AR17: =IF(AC17=0,0,((F17*AC17)-($Y$4*$Y$5*AC17)-Y$7*AC17)/1.21) -> 0 | AT17: =IF(AE17=0,0,((H17*AE17)-($Y$4*$Y$5*AE17)-AA$7*AE17)/1.21) -> 0 | AU17: =IF(AF17=0,0,((I17*AF17)-($Y$4*$Y$5*AF17)-AB$7*AF17)/1.21) -> 0 | AV17: =IF(AG17=0,0,((J17*AG17)-($Y$4*$Y$5*AG17)-AC$7*AG17)/1.21) -> 0 | AW17: =IF(AH17=0,0,((K17*AH17)-($Y$4*$Y$5*AH17)-AD$7*AH17)/1.21) -> 0 | AX17: =IF(AI17=0,0,((L17*AI17)-($Y$4*$Y$5*AI17)-AE$7*AI17)/1.21) -> 0 | AY17: =IF(AJ17=0,0,((M17*AJ17)-($Y$4*$Y$5*AJ17)-AF$7*AJ17)/1.21) -> 0 | AZ17: =IF(AK17=0,0,((O17*AK17)-($Z$4*$Z$5*AK17)-AD8*AK17)/1.21) -> 0 | BA17: =IF(AL17=0,0,((N17*AL17)-($Y$4*$Y$5*AL17)-AH$7*AL17)/1.21) -> 0 | BB17: =IF(AM17=0,0,((P17*AM17)-($Y$4*$Y$5*AM17)-AI$7*AM17)/1.21) -> 0 | BC17: =IF(AN17=0,0,((Q17*AN17)-($Y$4*$Y$5*AN17)-AJ$7*AN17)/1.21) -> 0 | BD17: =IF(AO17=0,0,((R17*AO17)-($Y$4*$Y$5*AO17)-AK$7*AO17)/1.21) -> 0 | BE17: =SUM(AR17:BD17) -> 0 | BJ17: Online Revenue
B18: Internet Rate / WIG Rate / BAR 3 | E18: 0.2 | F18: =IF(COUNTA($E18),F$11-(F$11*$E18),0) -> 5200000 | G18: =IF(COUNTA($E18),G$11-(G$11*$E18),0) -> 5600000 | H18: =IF(COUNTA($E18),H$11-(H$11*$E18),0) -> 5920000 | I18: =IF(COUNTA($E18),I$11-(I$11*$E18),0) -> 7360000 | J18: =IF(COUNTA($E18),J$11-(J$11*$E18),0) -> 8880000 | K18: =IF(COUNTA($E18),K$11-(K$11*$E18),0) -> 11040000 | L18: =IF(COUNTA($E18),L$11-(L$11*$E18),0) -> 11760000 | M18: =IF(COUNTA($E18),M$11-(M$11*$E18),0) -> 14720000 | ... R18: =IF(COUNTA($E18),R$11-(R$11*$E18),0) -> 44880000 | T18: Room Revenue | U18: : | V18: 1.8761209e+11 | Y18: 0 | AC18: =$AC$15*Y18 -> 0 | AD18: =$AD$15*Y18 -> 0 | AE18: =$AE$15*Y18 -> 0 | AF18: =$AF$15*Y18 -> 0 | AG18: =$AG$15*Y18 -> 0 | AH18: =$AH$15*Y18 -> 0 | AI18: =$AI$15*Y18 -> 0 | AJ18: =$AJ$15*Y18 -> 0 | AK18: =$AK$15*Y18 -> 0 | AL18: =$AL$15*Y18 -> 0 | AM18: =$AM$15*Y18 -> 0 | AN18: =$AN$15*Y18 -> 0 | AO18: =$AO$15*Y18 -> 0 | AP18: =SUM(AC18:AO18) -> 0 | AR18: =IF(AC18=0,0,((F18*AC18)-($Y$4*$Y$5*AC18)-Y$7*AC18)/1.21) -> 0 | AT18: =IF(AE18=0,0,((H18*AE18)-($Y$4*$Y$5*AE18)-AA$7*AE18)/1.21) -> 0 | AU18: =IF(AF18=0,0,((I18*AF18)-($Y$4*$Y$5*AF18)-AB$7*AF18)/1.21) -> 0 | AV18: =IF(AG18=0,0,((J18*AG18)-($Y$4*$Y$5*AG18)-AC$7*AG18)/1.21) -> 0 | AW18: =IF(AH18=0,0,((K18*AH18)-($Y$4*$Y$5*AH18)-AD$7*AH18)/1.21) -> 0 | AX18: =IF(AI18=0,0,((L18*AI18)-($Y$4*$Y$5*AI18)-AE$7*AI18)/1.21) -> 0 | AY18: =IF(AJ18=0,0,((M18*AJ18)-($Y$4*$Y$5*AJ18)-AF$7*AJ18)/1.21) -> 0 | AZ18: =IF(AK18=0,0,((O18*AK18)-($Z$4*$Z$5*AK18)-AD9*AK18)/1.21) -> 0 | BA18: =IF(AL18=0,0,((N18*AL18)-($Y$4*$Y$5*AL18)-AH$7*AL18)/1.21) -> 0 | BB18: =IF(AM18=0,0,((P18*AM18)-($Y$4*$Y$5*AM18)-AI$7*AM18)/1.21) -> 0 | BC18: =IF(AN18=0,0,((Q18*AN18)-($Y$4*$Y$5*AN18)-AJ$7*AN18)/1.21) -> 0 | BD18: =IF(AO18=0,0,((R18*AO18)-($Y$4*$Y$5*AO18)-AK$7*AO18)/1.21) -> 0 | BE18: =SUM(AR18:BD18) -> 0 | BJ18: AVG OTA Comm Level
B19: Internet Rate / WIG Rate / BAR 4 | E19: 0.25 | F19: =IF(COUNTA($E19),F$11-(F$11*$E19),0) -> 4875000 | G19: =IF(COUNTA($E19),G$11-(G$11*$E19),0) -> 5250000 | H19: =IF(COUNTA($E19),H$11-(H$11*$E19),0) -> 5550000 | I19: =IF(COUNTA($E19),I$11-(I$11*$E19),0) -> 6900000 | J19: =IF(COUNTA($E19),J$11-(J$11*$E19),0) -> 8325000 | K19: =IF(COUNTA($E19),K$11-(K$11*$E19),0) -> 10350000 | L19: =IF(COUNTA($E19),L$11-(L$11*$E19),0) -> 11025000 | M19: =IF(COUNTA($E19),M$11-(M$11*$E19),0) -> 13800000 | ... R19: =IF(COUNTA($E19),R$11-(R$11*$E19),0) -> 42075000 | T19: Average Room Rate | U19: : | V19: =V18/V17 -> 1302254.9 | Y19: 0 | AC19: =$AC$15*Y19 -> 0 | AD19: =$AD$15*Y19 -> 0 | AE19: =$AE$15*Y19 -> 0 | AF19: =$AF$15*Y19 -> 0 | AG19: =$AG$15*Y19 -> 0 | AH19: =$AH$15*Y19 -> 0 | AI19: =$AI$15*Y19 -> 0 | AJ19: =$AJ$15*Y19 -> 0 | AK19: =$AK$15*Y19 -> 0 | AL19: =$AL$15*Y19 -> 0 | AM19: =$AM$15*Y19+7.5 -> 7.5 | AN19: =$AN$15*Y19 -> 0 | AO19: =$AO$15*Y19 -> 0 | AP19: =SUM(AC19:AO19) -> 7.5 | AR19: =IF(AC19=0,0,((F19*AC19)-($Y$4*$Y$5*AC19)-Y$7*AC19)/1.21) -> 0 | AT19: =IF(AE19=0,0,((H19*AE19)-($Y$4*$Y$5*AE19)-AA$7*AE19)/1.21) -> 0 | AU19: =IF(AF19=0,0,((I19*AF19)-($Y$4*$Y$5*AF19)-AB$7*AF19)/1.21) -> 0 | AV19: =IF(AG19=0,0,((J19*AG19)-($Y$4*$Y$5*AG19)-AC$7*AG19)/1.21) -> 0 | AW19: =IF(AH19=0,0,((K19*AH19)-($Y$4*$Y$5*AH19)-AD$7*AH19)/1.21) -> 0 | AX19: =IF(AI19=0,0,((L19*AI19)-($Y$4*$Y$5*AI19)-AE$7*AI19)/1.21) -> 0 | AY19: =IF(AJ19=0,0,((M19*AJ19)-($Y$4*$Y$5*AJ19)-AF$7*AJ19)/1.21) -> 0 | AZ19: =IF(AK19=0,0,((O19*AK19)-(Z4*Z5*AK19)-AD7*AK19)/1.21) -> 0 | BA19: =IF(AL19=0,0,((N19*AL19)-($Y$4*$Y$5*AL19)-AH$7*AL19)/1.21) -> 0 | BB19: =IF(AM19=0,0,((P19*AM19)-($Y$4*$Y$5*AM19)-AI$7*AM19)/1.21) -> 93904959 | BC19: =IF(AN19=0,0,((Q19*AN19)-($Y$4*$Y$5*AN19)-AJ$7*AN19)/1.21) -> 0 | BD19: =IF(AO19=0,0,((R19*AO19)-($Y$4*$Y$5*AO19)-AK$7*AO19)/1.21) -> 0 | BE19: =SUM(AR19:BD19) -> 93904959 | BJ19: OTA Comm | BL19: 0.32
B20: Internet Rate / WIG Rate / BAR 5 | E20: 0.3 | F20: =IF(COUNTA($E20),F$11-(F$11*$E20),0) -> 4550000 | G20: =IF(COUNTA($E20),G$11-(G$11*$E20),0) -> 4900000 | H20: =IF(COUNTA($E20),H$11-(H$11*$E20),0) -> 5180000 | I20: =IF(COUNTA($E20),I$11-(I$11*$E20),0) -> 6440000 | J20: =IF(COUNTA($E20),J$11-(J$11*$E20),0) -> 7770000 | K20: =IF(COUNTA($E20),K$11-(K$11*$E20),0) -> 9660000 | L20: =IF(COUNTA($E20),L$11-(L$11*$E20),0) -> 10290000 | M20: =IF(COUNTA($E20),M$11-(M$11*$E20),0) -> 12880000 | ... R20: =IF(COUNTA($E20),R$11-(R$11*$E20),0) -> 39270000 | Y20: 0 | AC20: =$AC$15*Y20 -> 0 | AD20: =$AD$15*Y20 -> 0 | AE20: =$AE$15*Y20 -> 0 | AF20: =$AF$15*Y20 -> 0 | AG20: =$AG$15*Y20 -> 0 | AH20: =$AH$15*Y20 -> 0 | AI20: =$AI$15*Y20 -> 0 | AJ20: =$AJ$15*Y20 -> 0 | AK20: =$AK$15*Y20 -> 0 | AL20: =$AL$15*Y20 -> 0 | AM20: 0 | AN20: =$AN$15*Y20 -> 0 | AO20: =$AO$15*Y20 -> 0 | AP20: =SUM(AC20:AO20) -> 0 | AR20: =IF(AC20=0,0,((F20*AC20)-($Y$4*$Y$5*AC20)-Y$7*AC20)/1.21) -> 0 | AS20: =IF(AD20=0,0,((G20*AD20)-($Y$4*$Y$5*AD20)-Z$7*AD20)/1.21) -> 0 | AT20: =IF(AE20=0,0,((H20*AE20)-($Y$4*$Y$5*AE20)-AA$7*AE20)/1.21) -> 0 | AU20: =IF(AF20=0,0,((I20*AF20)-($Y$4*$Y$5*AF20)-AB$7*AF20)/1.21) -> 0 | AV20: =IF(AG20=0,0,((J20*AG20)-($Y$4*$Y$5*AG20)-AC$7*AG20)/1.21) -> 0 | AW20: =IF(AH20=0,0,((K20*AH20)-($Y$4*$Y$5*AH20)-AD$7*AH20)/1.21) -> 0 | AX20: =IF(AI20=0,0,((L20*AI20)-($Y$4*$Y$5*AI20)-AE$7*AI20)/1.21) -> 0 | AY20: =IF(AJ20=0,0,((M20*AJ20)-($Y$4*$Y$5*AJ20)-AF$7*AJ20)/1.21) -> 0 | AZ20: =IF(AK20=0,0,((O20*AK20)-($Z$4*$Z$5*AK20)-AD11*AK20)/1.21) -> 0 | BA20: =IF(AL20=0,0,((N20*AL20)-($Y$4*$Y$5*AL20)-AH$7*AL20)/1.21) -> 0 | BB20: =IF(AM20=0,0,((P20*AM20)-($Y$4*$Y$5*AM20)-AI$7*AM20)/1.21) -> 0 | BC20: =IF(AN20=0,0,((Q20*AN20)-($Y$4*$Y$5*AN20)-AJ$7*AN20)/1.21) -> 0 | BD20: =IF(AO20=0,0,((R20*AO20)-($Y$4*$Y$5*AO20)-AK$7*AO20)/1.21) -> 0 | BE20: =SUM(AR20:BD20) -> 0 | BJ20: OTA + FIT Revenue
B21: Internet Rate / WIG Rate / BAR 6 | E21: 0.4 | F21: =IF(COUNTA($E21),F$11-(F$11*$E21),0) -> 3900000 | G21: =IF(COUNTA($E21),G$11-(G$11*$E21),0) -> 4200000 | H21: =IF(COUNTA($E21),H$11-(H$11*$E21),0) -> 4440000 | I21: =IF(COUNTA($E21),I$11-(I$11*$E21),0) -> 5520000 | J21: =IF(COUNTA($E21),J$11-(J$11*$E21),0) -> 6660000 | K21: =IF(COUNTA($E21),K$11-(K$11*$E21),0) -> 8280000 | L21: =IF(COUNTA($E21),L$11-(L$11*$E21),0) -> 8820000 | M21: =IF(COUNTA($E21),M$11-(M$11*$E21),0) -> 11040000 | ... R21: =IF(COUNTA($E21),R$11-(R$11*$E21),0) -> 33660000 | T21: RATE STRUCTURE RESULT : | Y21: 0 | AC21: =$AC$15*Y21 -> 0 | AD21: =$AD$15*Y21 -> 0 | AE21: =$AE$15*Y21 -> 0 | AF21: =$AF$15*Y21 -> 0 | AG21: =$AG$15*Y21 -> 0 | AH21: =$AH$15*Y21 -> 0 | AI21: =$AI$15*Y21 -> 0 | AJ21: =$AJ$15*Y21 -> 0 | AK21: =$AK$15*Y21 -> 0 | AL21: =$AL$15*Y21 -> 0 | AM21: =$AM$15*Y21 -> 0 | AN21: =$AN$15*Y21 -> 0 | AO21: =$AO$15*Y21 -> 0 | AP21: =SUM(AC21:AO21) -> 0 | AR21: =IF(AC21=0,0,((F21*AC21)-($Y$4*$Y$5*AC21)-Y$7*AC21)/1.21) -> 0 | AS21: =IF(AD21=0,0,((G21*AD21)-($Y$4*$Y$5*AD21)-Z$7*AD21)/1.21) -> 0 | AT21: =IF(AE21=0,0,((H21*AE21)-($Y$4*$Y$5*AE21)-AA$7*AE21)/1.21) -> 0 | AU21: =IF(AF21=0,0,((I21*AF21)-($Y$4*$Y$5*AF21)-AB$7*AF21)/1.21) -> 0 | AV21: =IF(AG21=0,0,((J21*AG21)-($Y$4*$Y$5*AG21)-AC$7*AG21)/1.21) -> 0 | AW21: =IF(AH21=0,0,((K21*AH21)-($Y$4*$Y$5*AH21)-AD$7*AH21)/1.21) -> 0 | AX21: =IF(AI21=0,0,((L21*AI21)-($Y$4*$Y$5*AI21)-AE$7*AI21)/1.21) -> 0 | AY21: =IF(AJ21=0,0,((M21*AJ21)-($Y$4*$Y$5*AJ21)-AF$7*AJ21)/1.21) -> 0 | AZ21: =IF(AK21=0,0,((O21*AK21)-($Z$4*$Z$5*AK21)-AD14*AK21)/1.21) -> 0 | BA21: =IF(AL21=0,0,((N21*AL21)-($Y$4*$Y$5*AL21)-AH$7*AL21)/1.21) -> 0 | BB21: =IF(AM21=0,0,((P21*AM21)-($Y$4*$Y$5*AM21)-AI$7*AM21)/1.21) -> 0 | BC21: =IF(AN21=0,0,((Q21*AN21)-($Y$4*$Y$5*AN21)-AJ$7*AN21)/1.21) -> 0 | BD21: =IF(AO21=0,0,((R21*AO21)-($Y$4*$Y$5*AO21)-AK$7*AO21)/1.21) -> 0 | BE21: =SUM(AR21:BD21) -> 0
B22: Internet Rate / WIG Rate / BAR 7 | E22: 0.425 | F22: =IF(COUNTA($E22),F$11-(F$11*$E22),0) -> 3737500 | G22: =IF(COUNTA($E22),G$11-(G$11*$E22),0) -> 4025000 | H22: =IF(COUNTA($E22),H$11-(H$11*$E22),0) -> 4255000 | I22: =IF(COUNTA($E22),I$11-(I$11*$E22),0) -> 5290000 | J22: =IF(COUNTA($E22),J$11-(J$11*$E22),0) -> 6382500 | K22: =IF(COUNTA($E22),K$11-(K$11*$E22),0) -> 7935000 | L22: =IF(COUNTA($E22),L$11-(L$11*$E22),0) -> 8452500 | M22: =IF(COUNTA($E22),M$11-(M$11*$E22),0) -> 10580000 | ... R22: =IF(COUNTA($E22),R$11-(R$11*$E22),0) -> 32257500 | T22: Room Sold | U22: : | V22: =SUM(AC15:AO15) -> 144067.09 | Y22: 0 | AC22: =$AC$15*Y22 -> 0 | AD22: =$AD$15*Y22 -> 0 | AE22: =$AE$15*Y22 -> 0 | AF22: =$AF$15*Y22 -> 0 | AG22: =$AG$15*Y22 -> 0 | AH22: =$AH$15*Y22 -> 0 | AI22: =$AI$15*Y22 -> 0 | AJ22: =$AJ$15*Y22 -> 0 | AK22: =$AK$15*Y22 -> 0 | AL22: =$AL$15*Y22 -> 0 | AM22: =$AM$15*Y22 -> 0 | AN22: =$AN$15*Y22 -> 0 | AO22: =$AO$15*Y22 -> 0 | AP22: =SUM(AC22:AO22) -> 0 | AR22: =IF(AC22=0,0,((F22*AC22)-($Y$4*$Y$5*AC22)-Y$7*AC22)/1.21) -> 0 | AS22: =IF(AD22=0,0,((G22*AD22)-($Y$4*$Y$5*AD22)-Z$7*AD22)/1.21) -> 0 | AT22: =IF(AE22=0,0,((H22*AE22)-($Y$4*$Y$5*AE22)-AA$7*AE22)/1.21) -> 0 | AU22: =IF(AF22=0,0,((I22*AF22)-($Y$4*$Y$5*AF22)-AB$7*AF22)/1.21) -> 0 | AV22: =IF(AG22=0,0,((J22*AG22)-($Y$4*$Y$5*AG22)-AC$7*AG22)/1.21) -> 0 | AW22: =IF(AH22=0,0,((K22*AH22)-($Y$4*$Y$5*AH22)-AD$7*AH22)/1.21) -> 0 | AX22: =IF(AI22=0,0,((L22*AI22)-($Y$4*$Y$5*AI22)-AE$7*AI22)/1.21) -> 0 | AY22: =IF(AJ22=0,0,((M22*AJ22)-($Y$4*$Y$5*AJ22)-AF$7*AJ22)/1.21) -> 0 | AZ22: =IF(AK22=0,0,((O22*AK22)-($Z$4*$Z$5*AK22)-AD15*AK22)/1.21) -> 0 | BA22: =IF(AL22=0,0,((N22*AL22)-($Y$4*$Y$5*AL22)-AH$7*AL22)/1.21) -> 0 | BB22: =IF(AM22=0,0,((P22*AM22)-($Y$4*$Y$5*AM22)-AI$7*AM22)/1.21) -> 0 | BC22: =IF(AN22=0,0,((Q22*AN22)-($Y$4*$Y$5*AN22)-AJ$7*AN22)/1.21) -> 0 | BD22: =IF(AO22=0,0,((R22*AO22)-($Y$4*$Y$5*AO22)-AK$7*AO22)/1.21) -> 0 | BE22: =SUM(AR22:BD22) -> 0 | BL22: 2248212 | BM22: =F22-BL22 -> 1489288 | BN22: =BM22/F22 -> 0.39847171
B23: Internet Rate / WIG Rate / BAR 8 | E23: 0.45 | F23: =IF(COUNTA($E23),F$11-(F$11*$E23),0) -> 3575000 | G23: =IF(COUNTA($E23),G$11-(G$11*$E23),0) -> 3850000 | H23: =IF(COUNTA($E23),H$11-(H$11*$E23),0) -> 4070000 | I23: =IF(COUNTA($E23),I$11-(I$11*$E23),0) -> 5060000 | J23: =IF(COUNTA($E23),J$11-(J$11*$E23),0) -> 6105000 | K23: =IF(COUNTA($E23),K$11-(K$11*$E23),0) -> 7590000 | L23: =IF(COUNTA($E23),L$11-(L$11*$E23),0) -> 8085000 | M23: =IF(COUNTA($E23),M$11-(M$11*$E23),0) -> 10120000 | ... R23: =IF(COUNTA($E23),R$11-(R$11*$E23),0) -> 30855000 | T23: Room Revenue | U23: : | V23: =SUM(BE16:BE86) -> #REF! | Y23: 0 | AC23: =$AC$15*Y23 -> 0 | AD23: =$AD$15*Y23 -> 0 | AE23: =$AE$15*Y23 -> 0 | AF23: =$AF$15*Y23 -> 0 | AG23: =$AG$15*Y23 -> 0 | AH23: =$AH$15*Y23 -> 0 | AI23: =$AI$15*Y23 -> 0 | AJ23: =$AJ$15*Y23 -> 0 | AK23: =$AK$15*Y23 -> 0 | AL23: =$AL$15*Y23 -> 0 | AM23: =$AM$15*Y23 -> 0 | AN23: =$AN$15*Y23 -> 0 | AO23: =$AO$15*Y23 -> 0 | AP23: =SUM(AC23:AO23) -> 0 | AR23: =IF(AC23=0,0,((F23*AC23)-($Y$4*$Y$5*AC23)-Y$7*AC23)/1.21) -> 0 | AS23: =IF(AD23=0,0,((G23*AD23)-($Y$4*$Y$5*AD23)-Z$7*AD23)/1.21) -> 0 | AT23: =IF(AE23=0,0,((H23*AE23)-($Y$4*$Y$5*AE23)-AA$7*AE23)/1.21) -> 0 | AU23: =IF(AF23=0,0,((I23*AF23)-($Y$4*$Y$5*AF23)-AB$7*AF23)/1.21) -> 0 | AV23: =IF(AG23=0,0,((J23*AG23)-($Y$4*$Y$5*AG23)-AC$7*AG23)/1.21) -> 0 | AW23: =IF(AH23=0,0,((K23*AH23)-($Y$4*$Y$5*AH23)-AD$7*AH23)/1.21) -> 0 | AX23: =IF(AI23=0,0,((L23*AI23)-($Y$4*$Y$5*AI23)-AE$7*AI23)/1.21) -> 0 | AY23: =IF(AJ23=0,0,((M23*AJ23)-($Y$4*$Y$5*AJ23)-AF$7*AJ23)/1.21) -> 0 | AZ23: =IF(AK23=0,0,((O23*AK23)-($Z$4*$Z$5*AK23)-AD16*AK23)/1.21) -> 0 | BA23: =IF(AL23=0,0,((N23*AL23)-($Y$4*$Y$5*AL23)-AH$7*AL23)/1.21) -> 0 | BB23: =IF(AM23=0,0,((P23*AM23)-($Y$4*$Y$5*AM23)-AI$7*AM23)/1.21) -> 0 | BC23: =IF(AN23=0,0,((Q23*AN23)-($Y$4*$Y$5*AN23)-AJ$7*AN23)/1.21) -> 0 | BD23: =IF(AO23=0,0,((R23*AO23)-($Y$4*$Y$5*AO23)-AK$7*AO23)/1.21) -> 0 | BE23: =SUM(AR23:BD23) -> 0 | BL23: =F22 - (F22*BL19) -> 2541500 | BM23: =BL23-(BL23*15%) -> 2160275 | BN23: 2070000
B24: Internet Rate / WIG Rate / BAR 9 | E24: 0.475 | F24: =IF(COUNTA($E24),F$11-(F$11*$E24),0) -> 3412500 | G24: =IF(COUNTA($E24),G$11-(G$11*$E24),0) -> 3675000 | H24: =IF(COUNTA($E24),H$11-(H$11*$E24),0) -> 3885000 | I24: =IF(COUNTA($E24),I$11-(I$11*$E24),0) -> 4830000 | J24: =IF(COUNTA($E24),J$11-(J$11*$E24),0) -> 5827500 | K24: =IF(COUNTA($E24),K$11-(K$11*$E24),0) -> 7245000 | L24: =IF(COUNTA($E24),L$11-(L$11*$E24),0) -> 7717500 | M24: =IF(COUNTA($E24),M$11-(M$11*$E24),0) -> 9660000 | ... R24: =IF(COUNTA($E24),R$11-(R$11*$E24),0) -> 29452500 | T24: Average Room Rate | U24: : | V24: =V23/V22 -> #REF! | Y24: 0 | AC24: =$AC$15*Y24 -> 0 | AD24: =$AD$15*Y24 -> 0 | AE24: =$AE$15*Y24 -> 0 | AF24: =$AF$15*Y24 -> 0 | AG24: =$AG$15*Y24 -> 0 | AH24: =$AH$15*Y24 -> 0 | AI24: =$AI$15*Y24 -> 0 | AJ24: =$AJ$15*Y24 -> 0 | AK24: =$AK$15*Y24 -> 0 | AL24: =$AL$15*Y24 -> 0 | AM24: =$AM$15*Y24 -> 0 | AN24: =$AN$15*Y24 -> 0 | AO24: =$AO$15*Y24 -> 0 | AP24: =SUM(AC24:AO24) -> 0 | AR24: =IF(AC24=0,0,((F24*AC24)-($Y$4*$Y$5*AC24)-Y$7*AC24)/1.21) -> 0 | AS24: =IF(AD24=0,0,((G24*AD24)-($Y$4*$Y$5*AD24)-Z$7*AD24)/1.21) -> 0 | AT24: =IF(AE24=0,0,((H24*AE24)-($Y$4*$Y$5*AE24)-AA$7*AE24)/1.21) -> 0 | AU24: =IF(AF24=0,0,((I24*AF24)-($Y$4*$Y$5*AF24)-AB$7*AF24)/1.21) -> 0 | AV24: =IF(AG24=0,0,((J24*AG24)-($Y$4*$Y$5*AG24)-AC$7*AG24)/1.21) -> 0 | AW24: =IF(AH24=0,0,((K24*AH24)-($Y$4*$Y$5*AH24)-AD$7*AH24)/1.21) -> 0 | AX24: =IF(AI24=0,0,((L24*AI24)-($Y$4*$Y$5*AI24)-AE$7*AI24)/1.21) -> 0 | AY24: =IF(AJ24=0,0,((M24*AJ24)-($Y$4*$Y$5*AJ24)-AF$7*AJ24)/1.21) -> 0 | AZ24: =IF(AK24=0,0,((O24*AK24)-($Z$4*$Z$5*AK24)-AD17*AK24)/1.21) -> 0 | BA24: =IF(AL24=0,0,((N24*AL24)-($Y$4*$Y$5*AL24)-AH$7*AL24)/1.21) -> 0 | BB24: =IF(AM24=0,0,((P24*AM24)-($Y$4*$Y$5*AM24)-AI$7*AM24)/1.21) -> 0 | BC24: =IF(AN24=0,0,((Q24*AN24)-($Y$4*$Y$5*AN24)-AJ$7*AN24)/1.21) -> 0 | BD24: =IF(AO24=0,0,((R24*AO24)-($Y$4*$Y$5*AO24)-AK$7*AO24)/1.21) -> 0 | BE24: =SUM(AR24:BD24) -> 0 | BM24: =BL22-BM23 -> 87937 | BN24: =BN23-BM23 -> -90275
B25: Internet Rate / WIG Rate / BAR 10 | E25: 0.5 | F25: =IF(COUNTA($E25),F$11-(F$11*$E25),0) -> 3250000 | G25: =IF(COUNTA($E25),G$11-(G$11*$E25),0) -> 3500000 | H25: =IF(COUNTA($E25),H$11-(H$11*$E25),0) -> 3700000 | I25: =IF(COUNTA($E25),I$11-(I$11*$E25),0) -> 4600000 | J25: =IF(COUNTA($E25),J$11-(J$11*$E25),0) -> 5550000 | K25: =IF(COUNTA($E25),K$11-(K$11*$E25),0) -> 6900000 | L25: =IF(COUNTA($E25),L$11-(L$11*$E25),0) -> 7350000 | M25: =IF(COUNTA($E25),M$11-(M$11*$E25),0) -> 9200000 | ... R25: =IF(COUNTA($E25),R$11-(R$11*$E25),0) -> 28050000 | Y25: 0 | AC25: =$AC$15*Y25 -> 0 | AD25: =$AD$15*Y25 -> 0 | AE25: =$AE$15*Y25 -> 0 | AF25: =$AF$15*Y25 -> 0 | AG25: =$AG$15*Y25 -> 0 | AH25: =$AH$15*Y25 -> 0 | AI25: =$AI$15*Y25 -> 0 | AJ25: =$AJ$15*Y25 -> 0 | AK25: =$AK$15*Y25 -> 0 | AL25: =$AL$15*Y25 -> 0 | AM25: =$AM$15*Y25 -> 0 | AN25: =$AN$15*Y25 -> 0 | AO25: =$AO$15*Y25 -> 0 | AP25: =SUM(AC25:AO25) -> 0 | AR25: =IF(AC25=0,0,((F25*AC25)-($Y$4*$Y$5*AC25)-Y$7*AC25)/1.21) -> 0 | AS25: =IF(AD25=0,0,((G25*AD25)-($Y$4*$Y$5*AD25)-Z$7*AD25)/1.21) -> 0 | AT25: =IF(AE25=0,0,((H25*AE25)-($Y$4*$Y$5*AE25)-AA$7*AE25)/1.21) -> 0 | AU25: =IF(AF25=0,0,((I25*AF25)-($Y$4*$Y$5*AF25)-AB$7*AF25)/1.21) -> 0 | AV25: =IF(AG25=0,0,((J25*AG25)-($Y$4*$Y$5*AG25)-AC$7*AG25)/1.21) -> 0 | AW25: =IF(AH25=0,0,((K25*AH25)-($Y$4*$Y$5*AH25)-AD$7*AH25)/1.21) -> 0 | AX25: =IF(AI25=0,0,((L25*AI25)-($Y$4*$Y$5*AI25)-AE$7*AI25)/1.21) -> 0 | AY25: =IF(AJ25=0,0,((M25*AJ25)-($Y$4*$Y$5*AJ25)-AF$7*AJ25)/1.21) -> 0 | AZ25: =IF(AK25=0,0,((O25*AK25)-($Z$4*$Z$5*AK25)-AD18*AK25)/1.21) -> 0 | BA25: =IF(AL25=0,0,((N25*AL25)-($Y$4*$Y$5*AL25)-AH$7*AL25)/1.21) -> 0 | BB25: =IF(AM25=0,0,((P25*AM25)-($Y$4*$Y$5*AM25)-AI$7*AM25)/1.21) -> 0 | BC25: =IF(AN25=0,0,((Q25*AN25)-($Y$4*$Y$5*AN25)-AJ$7*AN25)/1.21) -> 0 | BD25: =IF(AO25=0,0,((R25*AO25)-($Y$4*$Y$5*AO25)-AK$7*AO25)/1.21) -> 0 | BE25: =SUM(AR25:BD25) -> 0
B26: Loyalti Program - My Value dan Kerjasama Merchant | F26: =F28-(F28*5%) -> 2309450 | G26: =G28-(G28*5%) -> 2487100 | H26: =H28-(H28*5%) -> 2629220 | I26: =I28-(I28*5%) -> 3268760 | J26: =J28-(J28*5%) -> 3943830 | K26: =K28-(K28*5%) -> 4903140 | L26: =L28-(L28*5%) -> 5222910 | M26: =M28-(M28*5%) -> 6537520 | ... R26: =R28-(R28*5%) -> 30804510 | Y26: 0 | AC26: =$AC$15*Y26 -> 0 | AD26: =$AD$15*Y26 -> 0 | AE26: =$AE$15*Y26 -> 0 | AF26: =$AF$15*Y26 -> 0 | AG26: =$AG$15*Y26 -> 0 | AH26: =$AH$15*Y26 -> 0 | AI26: =$AI$15*Y26 -> 0 | AJ26: =$AJ$15*Y26 -> 0 | AK26: =$AK$15*Y26 -> 0 | AL26: =$AL$15*Y26 -> 0 | AM26: =$AM$15*Y26 -> 0 | AN26: =$AN$15*Y26 -> 0 | AO26: =$AO$15*Y26 -> 0 | AP26: =SUM(AC26:AO26) -> 0 | AR26: =IF(AC26=0,0,((F26*AC26)-($Y$4*$Y$5*AC26)-Y$7*AC26)/1.21) -> 0 | AS26: =IF(AD26=0,0,((G26*AD26)-($Y$4*$Y$5*AD26)-Z$7*AD26)/1.21) -> 0 | AT26: =IF(AE26=0,0,((H26*AE26)-($Y$4*$Y$5*AE26)-AA$7*AE26)/1.21) -> 0 | AU26: =IF(AF26=0,0,((I26*AF26)-($Y$4*$Y$5*AF26)-AB$7*AF26)/1.21) -> 0 | AV26: =IF(AG26=0,0,((J26*AG26)-($Y$4*$Y$5*AG26)-AC$7*AG26)/1.21) -> 0 | AW26: =IF(AH26=0,0,((K26*AH26)-($Y$4*$Y$5*AH26)-AD$7*AH26)/1.21) -> 0 | AX26: =IF(AI26=0,0,((L26*AI26)-($Y$4*$Y$5*AI26)-AE$7*AI26)/1.21) -> 0 | AY26: =IF(AJ26=0,0,((M26*AJ26)-($Y$4*$Y$5*AJ26)-AF$7*AJ26)/1.21) -> 0 | AZ26: =IF(AK26=0,0,((O26*AK26)-($Z$4*$Z$5*AK26)-AD19*AK26)/1.21) -> 0 | BA26: =IF(AL26=0,0,((N26*AL26)-($Y$4*$Y$5*AL26)-AH$7*AL26)/1.21) -> 0 | BB26: =IF(AM26=0,0,((P26*AM26)-($Y$4*$Y$5*AM26)-AI$7*AM26)/1.21) -> 0 | BC26: =IF(AN26=0,0,((Q26*AN26)-($Y$4*$Y$5*AN26)-AJ$7*AN26)/1.21) -> 0 | BD26: =IF(AO26=0,0,((R26*AO26)-($Y$4*$Y$5*AO26)-AK$7*AO26)/1.21) -> 0 | BE26: =SUM(AR26:BD26) -> 0
B27: BAR APPLIED | F27: 8 | G27: =$F$27 -> 8 | H27: =$F$27 -> 8 | I27: =$F$27 -> 8 | J27: =$F$27 -> 8 | K27: =$F$27 -> 8 | L27: =$F$27 -> 8 | M27: =$F$27 -> 8 | N27: =$F$27 -> 8 | O27: =$F$27 -> 8 | P27: 2 | Q27: =$F$27 -> 8 | R27: 2
B28: Staycation Offer | E28: 0.32 | F28: =CHOOSE(F$27, F$16, F$17, F$18, F$19, F$20, F$21, F$22, F$23,F$24,F$25) * (1 - $E28) -> 2431000 | G28: =CHOOSE(G$27, G$16, G$17, G$18, G$19, G$20, G$21, G$22, G$23,G$24,G$25) * (1 - $E28) -> 2618000 | H28: =CHOOSE(H$27, H$16, H$17, H$18, H$19, H$20, H$21, H$22, H$23,H$24,H$25) * (1 - $E28) -> 2767600 | I28: =CHOOSE(I$27, I$16, I$17, I$18, I$19, I$20, I$21, I$22, I$23,I$24,I$25) * (1 - $E28) -> 3440800 | J28: =CHOOSE(J$27, J$16, J$17, J$18, J$19, J$20, J$21, J$22, J$23,J$24,J$25) * (1 - $E28) -> 4151400 | K28: =CHOOSE(K$27, K$16, K$17, K$18, K$19, K$20, K$21, K$22, K$23,K$24,K$25) * (1 - $E28) -> 5161200 | L28: =CHOOSE(L$27, L$16, L$17, L$18, L$19, L$20, L$21, L$22, L$23,L$24,L$25) * (1 - $E28) -> 5497800 | M28: =CHOOSE(M$27, M$16, M$17, M$18, M$19, M$20, M$21, M$22, M$23,M$24,M$25) * (1 - $E28) -> 6881600 | ... R28: =CHOOSE(R$27, R$16, R$17, R$18, R$19, R$20, R$21, R$22, R$23,R$24,R$25) * (1 - $E28) -> 32425800 | T28: VARIANCE | Y28: 0.19 | AC28: =$AC$15*Y28 -> 9854.1893 | AD28: =$AD$15*Y28+472 -> 1840.6374 | AE28: =$AE$15*Y28 -> 12673.582 | AF28: =$AF$15*Y28+755.3 -> 2945.1198 | AG28: =$AG$15*Y28+164.4 -> 438.12748 | AH28: =$AH$15*Y28+94.4 -> 368.12748 | AI28: =$AI$15*Y28+47.2 -> 184.06374 | AJ28: =$AJ$15*Y28+47.2 -> 184.06374 | AK28: =$AK$15*Y28+37.8 -> 147.29099 | AL28: =$AL$15*Y28+94.4 -> 368.12748 | AM28: =$AM$15*Y28+15+9.4 -> 51.772748 | AN28: =$AN$15*Y28+9.4 -> 36.772748 | AO28: =$AO$15*Y28+9.4 -> 36.772748 | AP28: =SUM(AC28:AO28) -> 29128.648 | AR28: =IF(AC28=0,0,((F28*AC28)-($Y$4*$Y$5*AC28)-Y$7*AC28)/1.21)-323320739.77 -> 1.9474641e+10 | AS28: =IF(AD28=0,0,((G28*AD28)-($Y$4*$Y$5*AD28)-Z$7*AD28)/1.21) -> 3.98247e+09 | AT28: =IF(AE28=0,0,((H28*AE28)-($Y$4*$Y$5*AE28)-AA$7*AE28)/1.21)-323320737.77 -> 2.8664618e+10 | AU28: =IF(AF28=0,0,((I28*AF28)-($Y$4*$Y$5*AF28)-AB$7*AF28)/1.21)-323320737.77 -> 8.0515291e+09 | AV28: =IF(AG28=0,0,((J28*AG28)-($Y$4*$Y$5*AG28)-AC$7*AG28)/1.21) -> 1.5031756e+09 | AW28: =IF(AH28=0,0,((K28*AH28)-($Y$4*$Y$5*AH28)-AD$7*AH28)/1.21) -> 1.570231e+09 | AX28: =IF(AI28=0,0,((L28*AI28)-($Y$4*$Y$5*AI28)-AE$7*AI28)/1.21) -> 8.363187e+08 | AZ28: =IF(AK28=0,0,((O28*AK28)-($Z$4*$Z$5*AK28)-AD20*AK28)/1.21) -> 8.8104359e+08 | BA28: =IF(AL28=0,0,((N28*AL28)-($Y$4*$Y$5*AL28)-AH$7*AL28)/1.21) -> 2.2756971e+09 | BB28: =IF(AM28=0,0,((P28*AM28)-($Y$4*$Y$5*AM28)-AI$7*AM28)/1.21) -> 4.9956851e+08 | BC28: =IF(AN28=0,0,((Q28*AN28)-($Y$4*$Y$5*AN28)-AJ$7*AN28)/1.21) -> 3.0233885e+08 | BE28: =SUM(AR28:BD28) -> 6.8041632e+10
B29: Flexible Staycation Offer | E29: 0.27 | F29: =CHOOSE(F$27, F$16, F$17, F$18, F$19, F$20, F$21, F$22, F$23, F$24, F$25) * (1 - $E29) -> 2609750 | G29: =CHOOSE(G$27, G$16, G$17, G$18, G$19, G$20, G$21, G$22, G$23, G$24, G$25) * (1 - $E29) -> 2810500 | H29: =CHOOSE(H$27, H$16, H$17, H$18, H$19, H$20, H$21, H$22, H$23, H$24, H$25) * (1 - $E29) -> 2971100 | I29: =CHOOSE(I$27, I$16, I$17, I$18, I$19, I$20, I$21, I$22, I$23, I$24, I$25) * (1 - $E29) -> 3693800 | J29: =CHOOSE(J$27, J$16, J$17, J$18, J$19, J$20, J$21, J$22, J$23, J$24, J$25) * (1 - $E29) -> 4456650 | K29: =CHOOSE(K$27, K$16, K$17, K$18, K$19, K$20, K$21, K$22, K$23, K$24, K$25) * (1 - $E29) -> 5540700 | L29: =CHOOSE(L$27, L$16, L$17, L$18, L$19, L$20, L$21, L$22, L$23, L$24, L$25) * (1 - $E29) -> 5902050 | M29: =CHOOSE(M$27, M$16, M$17, M$18, M$19, M$20, M$21, M$22, M$23, M$24, M$25) * (1 - $E29) -> 7387600 | ... R29: =CHOOSE(R$27, R$16, R$17, R$18, R$19, R$20, R$21, R$22, R$23, R$24, R$25) * (1 - $E29) -> 34810050 | T29: Room Sold | U29: : | V29: =V22-V17 -> 0 | Y29: 0.09 | AC29: =$AC$15*Y29 -> 4667.7739 | AD29: =$AD$15*Y29 -> 648.30192 | AE29: =$AE$15*Y29 -> 6003.2758 | AF29: =$AF$15*Y29+1215.4 -> 2252.6831 | AG29: =$AG$15*Y29 -> 129.66038 | AH29: =$AH$15*Y29+151.9 -> 281.56038 | AI29: =$AI$15*Y29+76 -> 140.83019 | AJ29: =$AJ$15*Y29+76 -> 140.83019 | AK29: =$AK$15*Y29+60.8 -> 112.66415 | AL29: =$AL$15*Y29+151.9 -> 281.56038 | AM29: =$AM$15*Y29+15+15.2 -> 43.166038 | AN29: =$AN$15*Y29+15.2 -> 28.166038 | AO29: =$AO$15*Y29+15.2 -> 28.166038 | AP29: =SUM(AC29:AO29) -> 14758.638 | AR29: =IF(AC29=0,0,((F29*AC29)-($Y$4*$Y$5*AC29)-Y$7*AC29)/1.21)-323320737.77+134166431 -> 9.8783852e+09 | AS29: =IF(AD29=0,0,((G29*AD29)-($Y$4*$Y$5*AD29)-Z$7*AD29)/1.21)-323320737.77 -> 1.1825078e+09 | AT29: =IF(AE29=0,0,((H29*AE29)-($Y$4*$Y$5*AE29)-AA$7*AE29)/1.21)-323320737.77 -> 1.441745e+10 | AU29: =IF(AF29=0,0,((I29*AF29)-($Y$4*$Y$5*AF29)-AB$7*AF29)/1.21)-323320737.77 -> 6.5535063e+09 | AV29: =IF(AG29=0,0,((J29*AG29)-($Y$4*$Y$5*AG29)-AC$7*AG29)/1.21) -> 4.7756277e+08 | AW29: =IF(AH29=0,0,((K29*AH29)-($Y$4*$Y$5*AH29)-AD$7*AH29)/1.21) -> 1.2892906e+09 | AX29: =IF(AI29=0,0,((L29*AI29)-($Y$4*$Y$5*AI29)-AE$7*AI29)/1.21) -> 6.8693127e+08 | AZ29: =IF(AK29=0,0,((O29*AK29)-($Z$4*$Z$5*AK29)-AD21*AK29)/1.21) -> 7.2692123e+08 | BA29: =IF(AL29=0,0,((N29*AL29)-($Y$4*$Y$5*AL29)-AH$7*AL29)/1.21) -> 1.8685371e+09 | BB29: =IF(AM29=0,0,((P29*AM29)-($Y$4*$Y$5*AM29)-AI$7*AM29)/1.21) -> 4.4714665e+08 | BC29: =IF(AN29=0,0,((Q29*AN29)-($Y$4*$Y$5*AN29)-AJ$7*AN29)/1.21) -> 2.486037e+08 | BE29: =SUM(AR29:BD29) -> 3.7776843e+10
B30: EBO | E30: 0.35 | F30: =CHOOSE(F$27, F$16, F$17, F$18, F$19, F$20, F$21, F$22, F$23, F$24, F$25) * (1 - $E30) -> 2323750 | G30: =CHOOSE(G$27, G$16, G$17, G$18, G$19, G$20, G$21, G$22, G$23, G$24, G$25) * (1 - $E30) -> 2502500 | H30: =CHOOSE(H$27, H$16, H$17, H$18, H$19, H$20, H$21, H$22, H$23, H$24, H$25) * (1 - $E30) -> 2645500 | I30: =CHOOSE(I$27, I$16, I$17, I$18, I$19, I$20, I$21, I$22, I$23, I$24, I$25) * (1 - $E30) -> 3289000 | J30: =CHOOSE(J$27, J$16, J$17, J$18, J$19, J$20, J$21, J$22, J$23, J$24, J$25) * (1 - $E30) -> 3968250 | K30: =CHOOSE(K$27, K$16, K$17, K$18, K$19, K$20, K$21, K$22, K$23, K$24, K$25) * (1 - $E30) -> 4933500 | L30: =CHOOSE(L$27, L$16, L$17, L$18, L$19, L$20, L$21, L$22, L$23, L$24, L$25) * (1 - $E30) -> 5255250 | M30: =CHOOSE(M$27, M$16, M$17, M$18, M$19, M$20, M$21, M$22, M$23, M$24, M$25) * (1 - $E30) -> 6578000 | ... R30: =CHOOSE(R$27, R$16, R$17, R$18, R$19, R$20, R$21, R$22, R$23, R$24, R$25) * (1 - $E30) -> 30995250 | T30: Room Revenue | U30: : | V30: =V23-V18 -> #REF! | Y30: 0.09 | AC30: =$AC$15*Y30 -> 4667.7739 | AD30: =$AD$15*Y30+471.4 -> 1119.7019 | AE30: =$AE$15*Y30 -> 6003.2758 | AF30: =$AF$15*Y30+754.2 -> 1791.4831 | AG30: =$AG$15*Y30+188.5 -> 318.16038 | AH30: =$AH$15*Y30+94.3 -> 223.96038 | AI30: =$AI$15*Y30+47.1 -> 111.93019 | AJ30: =$AJ$15*Y30+47.1 -> 111.93019 | AK30: =$AK$15*Y30+37.7 -> 89.564154 | AL30: =$AL$15*Y30+94.3 -> 223.96038 | AM30: =$AM$15*Y30+15+9.4 -> 37.366038 | AN30: =$AN$15*Y30+9.4 -> 22.366038 | AO30: =$AO$15*Y30+9.4 -> 22.366038 | AP30: =SUM(AC30:AO30) -> 14743.838 | AR30: =IF(AC30=0,0,((F30*AC30)-($Y$4*$Y$5*AC30)-Y$7*AC30)/1.21)-323320737.77 -> 8.6409268e+09 | AS30: =IF(AD30=0,0,((G30*AD30)-($Y$4*$Y$5*AD30)-Z$7*AD30)/1.21) -> 2.3157472e+09 | AT30: =IF(AE30=0,0,((H30*AE30)-($Y$4*$Y$5*AE30)-AA$7*AE30)/1.21)-323320737.77-323320737.77-323320737.77-323320737.77-323320737.77 -> 1.150874e+10 | AU30: =IF(AF30=0,0,((I30*AF30)-($Y$4*$Y$5*AF30)-AB$7*AF30)/1.21) -> 4.8695767e+09 | AV30: =IF(AG30=0,0,((J30*AG30)-($Y$4*$Y$5*AG30)-AC$7*AG30)/1.21) -> 1.0434214e+09 | AW30: =IF(AH30=0,0,((K30*AH30)-($Y$4*$Y$5*AH30)-AD$7*AH30)/1.21) -> 9.1314757e+08 | AX30: =IF(AI30=0,0,((L30*AI30)-($Y$4*$Y$5*AI30)-AE$7*AI30)/1.21) -> 4.8613318e+08 | AZ30: =IF(AK30=0,0,((O30*AK30)-($Z$4*$Z$5*AK30)-AD22*AK30)/1.21) -> 5.1046016e+08 | BA30: =IF(AL30=0,0,((N30*AL30)-($Y$4*$Y$5*AL30)-AH$7*AL30)/1.21) -> 1.3234023e+09 | BB30: =IF(AM30=0,0,((P30*AM30)-($Y$4*$Y$5*AM30)-AI$7*AM30)/1.21) -> 3.4464766e+08 | BC30: =IF(AN30=0,0,((Q30*AN30)-($Y$4*$Y$5*AN30)-AJ$7*AN30)/1.21) -> 1.7577673e+08 | BE30: =SUM(AR30:BD30) -> 3.213198e+10
B31: GAP | F31: 0.12 | G31: 0.12 | H31: 0.12 | I31: 0.12 | J31: 0.12 | K31: 0.07 | L31: 0.07 | M31: 0.07 | N31: 0.07 | O31: 0.07 | P31: 0.07 | Q31: 0.07 | R31: 0.07
B32: Corporate New | F32: =CEILING(F28-(F28*F31),50000) -> 2150000 | G32: =CEILING(G28-(G28*G31),50000) -> 2350000 | H32: =CEILING(H28-(H28*H31),50000) -> 2450000 | I32: =CEILING(I28-(I28*I31),50000) -> 3050000 | J32: =CEILING(J28-(J28*J31),50000) -> 3700000 | K32: =CEILING(K28-(K28*K31),50000) -> 4800000 | L32: =CEILING(L28-(L28*L31),50000) -> 5150000 | M32: =CEILING(M28-(M28*M31),50000) -> 6400000 | ... R32: =CEILING(R28-(R28*R31),50000) -> 30200000 | X32: =SUM(Y32:Y40) -> 0.03 | Y32: 0 | Z32: 0.034439869 | AA32: 0.081267918 | AC32: =$AC$15*Y32 -> 0 | AD32: =$AD$15*Y32 -> 0 | AE32: =$AE$15*Y32 -> 0 | AF32: =$AF$15*Y32 -> 0 | AG32: =$AG$15*Y32 -> 0 | AH32: =$AH$15*Y32 -> 0 | AI32: =$AI$15*Y32 -> 0 | AJ32: =$AJ$15*Y32 -> 0 | AK32: =$AK$15*Y32 -> 0 | AL32: =$AL$15*Y32 -> 0 | AM32: =$AM$15*Y32 -> 0 | AN32: =$AN$15*Y32 -> 0 | AO32: =$AO$15*Y32 -> 0 | AP32: =SUM(AC32:AO32) -> 0 | AR32: =IF(AC32=0,0,((F32*AC32)-($Y$4*$Y$5*AC32)-Y$7*AC32)/1.21) -> 0 | AS32: =IF(AD32=0,0,((G32*AD32)-($Y$4*$Y$5*AD32)-Z$7*AD32)/1.21) -> 0 | AT32: =IF(AE32=0,0,((H32*AE32)-($Y$4*$Y$5*AE32)-AA$7*AE32)/1.21) -> 0 | AU32: =IF(AF32=0,0,((I32*AF32)-($Y$4*$Y$5*AF32)-AB$7*AF32)/1.21) -> 0 | AV32: =IF(AG32=0,0,((J32*AG32)-($Y$4*$Y$5*AG32)-AC$7*AG32)/1.21) -> 0 | AW32: =IF(AH32=0,0,((K32*AH32)-($Y$4*$Y$5*AH32)-AD$7*AH32)/1.21) -> 0 | AX32: =IF(AI32=0,0,((L32*AI32)-($Y$4*$Y$5*AI32)-AE$7*AI32)/1.21) -> 0 | AY32: =IF(AJ32=0,0,((M32*AJ32)-($Y$4*$Y$5*AJ32)-AF$7*AJ32)/1.21) -> 0 | AZ32: =IF(AK32=0,0,((O32*AK32)-($Z$4*$Z$5*AK32)-AD28*AK32)/1.21) -> 0 | BA32: =IF(AL32=0,0,((N32*AL32)-($Y$4*$Y$5*AL32)-AH$7*AL32)/1.21) -> 0 | BB32: =IF(AM32=0,0,((P32*AM32)-($Y$4*$Y$5*AM32)-AI$7*AM32)/1.21) -> 0 | BC32: =IF(AN32=0,0,((Q32*AN32)-($Y$4*$Y$5*AN32)-AJ$7*AN32)/1.21) -> 0 | BD32: =IF(AO32=0,0,((R32*AO32)-($Y$4*$Y$5*AO32)-AK$7*AO32)/1.21) -> 0 | BE32: =SUM(AR32:BD32) -> 0 | BF32: =SUM(BE32:BE40) -> 9.0623534e+09 | BG32: Corp | BH32: 7481949530 | BI32: =BH32-BF32 -> -1.5804038e+09
B33: Corporate Productive | F33: =F32-50000 -> 2100000 | G33: =G32-50000 -> 2300000 | H33: =H32-50000 -> 2400000 | I33: =I32-50000 -> 3000000 | J33: =J32-50000 -> 3650000 | K33: =K32-50000 -> 4750000 | L33: =L32-50000 -> 5100000 | M33: =M32-50000 -> 6350000 | ... R33: =R32-50000 -> 30150000 | Y33: 0.005 | AC33: =$AC$15*Y33 -> 259.32077 | AD33: =$AD$15*Y33 -> 36.016774 | AE33: =$AE$15*Y33 -> 333.51532 | AF33: =$AF$15*Y33 -> 57.626838 | AG33: =$AG$15*Y33 -> 7.2033547 | AH33: =$AH$15*Y33 -> 7.2033547 | AI33: =$AI$15*Y33 -> 3.6016774 | AJ33: =$AJ$15*Y33 -> 3.6016774 | AK33: =$AK$15*Y33 -> 2.8813419 | AL33: =$AL$15*Y33 -> 7.2033547 | AN33: =$AN$15*Y33 -> 0.72033547 | AO33: =$AO$15*Y33 -> 0.72033547 | AP33: =SUM(AC33:AO33) -> 719.61514 | AR33: =IF(AC33=0,0,((F33*AC33)-($Y$4*$Y$5*AC33)-Y$7*AC33)/1.21)+303641628 -> 7.5370247e+08 | AT33: =IF(AE33=0,0,((H33*AE33)-($Y$4*$Y$5*AE33)-AA$7*AE33)/1.21)+303641628 -> 9.6515962e+08 | AV33: =IF(AG33=0,0,((J33*AG33)-($Y$4*$Y$5*AG33)-AC$7*AG33)/1.21) -> 21729128 | BB33: =IF(AM33=0,0,((P33*AM33)-($Y$4*$Y$5*AM33)-AI$7*AM33)/1.21) -> 0 | BE33: =SUM(AR33:BD33) -> 1.7405912e+09
B34: Corporate Super Productive | F34: =F33-50000 -> 2050000 | G34: =G33-50000 -> 2250000 | H34: =H33-50000 -> 2350000 | I34: =I33-50000 -> 2950000 | J34: =J33-50000 -> 3600000 | K34: =K33-50000 -> 4700000 | L34: =L33-50000 -> 5050000 | M34: =M33-50000 -> 6300000 | ... R34: =R33-50000 -> 30100000 | Y34: 0.025 | AC34: =$AC$15*Y34 -> 1296.6038 | AD34: =$AD$15*Y34 -> 180.08387 | AE34: =$AE$15*Y34 -> 1667.5766 | AF34: =$AF$15*Y34 -> 288.13419 | AG34: =$AG$15*Y34 -> 36.016774 | AH34: =$AH$15*Y34 -> 36.016774 | AI34: =$AI$15*Y34 -> 18.008387 | AJ34: =$AJ$15*Y34 -> 18.008387 | AK34: =$AK$15*Y34 -> 14.406709 | AL34: =$AL$15*Y34 -> 36.016774 | AM34: =$AM$15*Y34 -> 3.6016774 | AN34: =$AN$15*Y34 -> 3.6016774 | AO34: =$AO$15*Y34 -> 3.6016774 | AP34: =SUM(AC34:AO34) -> 3601.6774 | AR34: =IF(AC34=0,0,((F34*AC34)-($Y$4*$Y$5*AC34)-Y$7*AC34)/1.21) -> 2.1967255e+09 | AS34: =IF(AD34=0,0,((G34*AD34)-($Y$4*$Y$5*AD34)-Z$7*AD34)/1.21) -> 3.348667e+08 | AT34: =IF(AE34=0,0,((H34*AE34)-($Y$4*$Y$5*AE34)-AA$7*AE34)/1.21) -> 3.2386819e+09 | AU34: =IF(AF34=0,0,((I34*AF34)-($Y$4*$Y$5*AF34)-AB$7*AF34)/1.21) -> 7.0247591e+08 | AV34: =IF(AG34=0,0,((J34*AG34)-($Y$4*$Y$5*AG34)-AC$7*AG34)/1.21) -> 1.0715734e+08 | AW34: =IF(AH34=0,0,((K34*AH34)-($Y$4*$Y$5*AH34)-AD$7*AH34)/1.21) -> 1.3989986e+08 | AX34: =IF(AI34=0,0,((L34*AI34)-($Y$4*$Y$5*AI34)-AE$7*AI34)/1.21) -> 75158970 | AY34: =IF(AJ34=0,0,((M34*AJ34)-($Y$4*$Y$5*AJ34)-AF$7*AJ34)/1.21) -> 93762675 | AZ34: =IF(AK34=0,0,((O34*AK34)-($Z$4*$Z$5*AK34)-AD30*AK34)/1.21) -> 78521094 | BA34: =IF(AL34=0,0,((N34*AL34)-($Y$4*$Y$5*AL34)-AH$7*AL34)/1.21) -> 2.0538491e+08 | BB34: =IF(AM34=0,0,((P34*AM34)-($Y$4*$Y$5*AM34)-AI$7*AM34)/1.21) -> 32147203 | BC34: =IF(AN34=0,0,((Q34*AN34)-($Y$4*$Y$5*AN34)-AJ$7*AN34)/1.21) -> 27384654 | BD34: =IF(AO34=0,0,((R34*AO34)-($Y$4*$Y$5*AO34)-AK$7*AO34)/1.21) -> 89595445 | BE34: =SUM(AR34:BD34) -> 7.3217622e+09
B35: NKA | F35: =F34-50000 -> 2000000 | G35: =G34-50000 -> 2200000 | H35: =H34-50000 -> 2300000 | I35: =I34-50000 -> 2900000 | J35: =J34-50000 -> 3550000 | K35: =K34-50000 -> 4650000 | L35: =L34-50000 -> 5000000 | M35: =M34-50000 -> 6250000 | ... R35: =R34-50000 -> 30050000 | Y35: 0 | AC35: =$AC$15*Y35 -> 0 | AD35: =$AD$15*Y35 -> 0 | AE35: =$AE$15*Y35 -> 0 | AF35: =$AF$15*Y35 -> 0 | AG35: =$AG$15*Y35 -> 0 | AH35: =$AH$15*Y35 -> 0 | AI35: =$AI$15*Y35 -> 0 | AJ35: =$AJ$15*Y35 -> 0 | AK35: =$AK$15*Y35 -> 0 | AL35: =$AL$15*Y35 -> 0 | AM35: =$AM$15*Y35 -> 0 | AN35: =$AN$15*Y35 -> 0 | AO35: =$AO$15*Y35 -> 0 | AP35: =SUM(AC35:AO35) -> 0 | AR35: =IF(AC35=0,0,((F35*AC35)-($Y$4*$Y$5*AC35)-Y$7*AC35)/1.21) -> 0 | AS35: =IF(AD35=0,0,((G35*AD35)-($Y$4*$Y$5*AD35)-Z$7*AD35)/1.21) -> 0 | AT35: =IF(AE35=0,0,((H35*AE35)-($Y$4*$Y$5*AE35)-AA$7*AE35)/1.21) -> 0 | AU35: =IF(AF35=0,0,((I35*AF35)-($Y$4*$Y$5*AF35)-AB$7*AF35)/1.21) -> 0 | AV35: =IF(AG35=0,0,((J35*AG35)-($Y$4*$Y$5*AG35)-AC$7*AG35)/1.21) -> 0 | AW35: =IF(AH35=0,0,((K35*AH35)-($Y$4*$Y$5*AH35)-AD$7*AH35)/1.21) -> 0 | AX35: =IF(AI35=0,0,((L35*AI35)-($Y$4*$Y$5*AI35)-AE$7*AI35)/1.21) -> 0 | AY35: =IF(AJ35=0,0,((M35*AJ35)-($Y$4*$Y$5*AJ35)-AF$7*AJ35)/1.21) -> 0 | AZ35: =IF(AK35=0,0,((O35*AK35)-($Z$4*$Z$5*AK35)-#REF!*AK35)/1.21) -> 0 | BA35: =IF(AL35=0,0,((N35*AL35)-($Y$4*$Y$5*AL35)-AH$7*AL35)/1.21) -> 0 | BB35: =IF(AM35=0,0,((P35*AM35)-($Y$4*$Y$5*AM35)-AI$7*AM35)/1.21) -> 0 | BC35: =IF(AN35=0,0,((Q35*AN35)-($Y$4*$Y$5*AN35)-AJ$7*AN35)/1.21) -> 0 | BD35: =IF(AO35=0,0,((R35*AO35)-($Y$4*$Y$5*AO35)-AK$7*AO35)/1.21) -> 0 | BE35: =SUM(AR35:BD35) -> 0
B36: Corporate Preffered 2 (ad hoc - based) | F36: =F35-50000 -> 1950000 | G36: =G35-50000 -> 2150000 | H36: =H35-50000 -> 2250000 | I36: =I35-50000 -> 2850000 | J36: =J35-50000 -> 3500000 | K36: =K35-50000 -> 4600000 | L36: =L35-50000 -> 4950000 | M36: =M35-50000 -> 6200000 | ... R36: =R35-50000 -> 30000000 | Y36: 0 | AC36: =$AC$15*Y36 -> 0 | AD36: =$AD$15*Y36 -> 0 | AE36: =$AE$15*Y36 -> 0 | AF36: =$AF$15*Y36 -> 0 | AG36: =$AG$15*Y36 -> 0 | AH36: =$AH$15*Y36 -> 0 | AI36: =$AI$15*Y36 -> 0 | AJ36: =$AJ$15*Y36 -> 0 | AK36: =$AK$15*Y36 -> 0 | AL36: =$AL$15*Y36 -> 0 | AM36: =$AM$15*Y36 -> 0 | AN36: =$AN$15*Y36 -> 0 | AO36: =$AO$15*Y36 -> 0 | AP36: =SUM(AC36:AO36) -> 0 | AR36: =IF(AC36=0,0,((F36*AC36)-($Y$4*$Y$5*AC36)-Y$7*AC36)/1.21) -> 0 | AS36: =IF(AD36=0,0,((G36*AD36)-($Y$4*$Y$5*AD36)-Z$7*AD36)/1.21) -> 0 | AT36: =IF(AE36=0,0,((H36*AE36)-($Y$4*$Y$5*AE36)-AA$7*AE36)/1.21) -> 0 | AU36: =IF(AF36=0,0,((I36*AF36)-($Y$4*$Y$5*AF36)-AB$7*AF36)/1.21) -> 0 | AV36: =IF(AG36=0,0,((J36*AG36)-($Y$4*$Y$5*AG36)-AC$7*AG36)/1.21) -> 0 | AW36: =IF(AH36=0,0,((K36*AH36)-($Y$4*$Y$5*AH36)-AD$7*AH36)/1.21) -> 0 | AX36: =IF(AI36=0,0,((L36*AI36)-($Y$4*$Y$5*AI36)-AE$7*AI36)/1.21) -> 0 | AY36: =IF(AJ36=0,0,((M36*AJ36)-($Y$4*$Y$5*AJ36)-AF$7*AJ36)/1.21) -> 0 | AZ36: =IF(AK36=0,0,((O36*AK36)-($Z$4*$Z$5*AK36)-#REF!*AK36)/1.21) -> 0 | BA36: =IF(AL36=0,0,((N36*AL36)-($Y$4*$Y$5*AL36)-AH$7*AL36)/1.21) -> 0 | BB36: =IF(AM36=0,0,((P36*AM36)-($Y$4*$Y$5*AM36)-AI$7*AM36)/1.21) -> 0 | BC36: =IF(AN36=0,0,((Q36*AN36)-($Y$4*$Y$5*AN36)-AJ$7*AN36)/1.21) -> 0 | BD36: =IF(AO36=0,0,((R36*AO36)-($Y$4*$Y$5*AO36)-AK$7*AO36)/1.21) -> 0 | BE36: =SUM(AR36:BD36) -> 0
B37: Corporate Preffered 3 | F37: 0 | G37: =IF(F37=0,0,F37+$G$15) -> 0 | H37: =IF(F37=0,0,F37+$H$15) -> 0 | I37: =IF(F37=0,0,F37+$I$15) -> 0 | J37: =F37+$J$15 -> 0 | K37: =F37+$K$15 -> 0 | L37: =F37+$L$15 -> 0 | M37: =G37+$L$15 -> 0 | N37: =I37+$L$15 -> 0 | O37: =H37+$L$15 -> 0 | P37: =J37+$L$15 -> 0 | Q37: =K37+$L$15 -> 0 | R37: =L37+$L$15 -> 0 | Y37: 0 | AC37: =$AC$15*Y37 -> 0 | AD37: =$AD$15*Y37 -> 0 | AE37: =$AE$15*Y37 -> 0 | AF37: =$AF$15*Y37 -> 0 | AG37: =$AG$15*Y37 -> 0 | AH37: =$AH$15*Y37 -> 0 | AI37: =$AI$15*Y37 -> 0 | AJ37: =$AJ$15*Y37 -> 0 | AK37: =$AK$15*Y37 -> 0 | AL37: =$AL$15*Y37 -> 0 | AM37: =$AM$15*Y37 -> 0 | AN37: =$AN$15*Y37 -> 0 | AO37: =$AO$15*Y37 -> 0 | AP37: =SUM(AC37:AO37) -> 0 | AR37: =IF(AC37=0,0,((F37*AC37)-($Y$4*$Y$5*AC37)-Y$7*AC37)/1.21) -> 0 | AS37: =IF(AD37=0,0,((G37*AD37)-($Y$4*$Y$5*AD37)-Z$7*AD37)/1.21) -> 0 | AT37: =IF(AE37=0,0,((H37*AE37)-($Y$4*$Y$5*AE37)-AA$7*AE37)/1.21) -> 0 | AU37: =IF(AF37=0,0,((I37*AF37)-($Y$4*$Y$5*AF37)-AB$7*AF37)/1.21) -> 0 | AV37: =IF(AG37=0,0,((J37*AG37)-($Y$4*$Y$5*AG37)-AC$7*AG37)/1.21) -> 0 | AW37: =IF(AH37=0,0,((K37*AH37)-($Y$4*$Y$5*AH37)-AD$7*AH37)/1.21) -> 0 | AX37: =IF(AI37=0,0,((L37*AI37)-($Y$4*$Y$5*AI37)-AE$7*AI37)/1.21) -> 0 | AY37: =IF(AJ37=0,0,((M37*AJ37)-($Y$4*$Y$5*AJ37)-AF$7*AJ37)/1.21) -> 0 | AZ37: =IF(AK37=0,0,((O37*AK37)-($Z$4*$Z$5*AK37)-#REF!*AK37)/1.21) -> 0 | BA37: =IF(AL37=0,0,((N37*AL37)-($Y$4*$Y$5*AL37)-AH$7*AL37)/1.21) -> 0 | BB37: =IF(AM37=0,0,((P37*AM37)-($Y$4*$Y$5*AM37)-AI$7*AM37)/1.21) -> 0 | BC37: =IF(AN37=0,0,((Q37*AN37)-($Y$4*$Y$5*AN37)-AJ$7*AN37)/1.21) -> 0 | BD37: =IF(AO37=0,0,((R37*AO37)-($Y$4*$Y$5*AO37)-AK$7*AO37)/1.21) -> 0 | BE37: =SUM(AR37:BD37) -> 0
B38: Corporate Preffered 4 | F38: 0 | G38: =IF(F38=0,0,F38+$G$15) -> 0 | H38: =IF(F38=0,0,F38+$H$15) -> 0 | I38: =IF(F38=0,0,F38+$I$15) -> 0 | J38: =F38+$J$15 -> 0 | K38: =F38+$K$15 -> 0 | L38: =F38+$L$15 -> 0 | M38: =G38+$L$15 -> 0 | N38: =I38+$L$15 -> 0 | O38: =H38+$L$15 -> 0 | P38: =J38+$L$15 -> 0 | Q38: =K38+$L$15 -> 0 | R38: =L38+$L$15 -> 0 | Y38: 0 | AC38: =$AC$15*Y38 -> 0 | AD38: =$AD$15*Y38 -> 0 | AE38: =$AE$15*Y38 -> 0 | AF38: =$AF$15*Y38 -> 0 | AG38: =$AG$15*Y38 -> 0 | AH38: =$AH$15*Y38 -> 0 | AI38: =$AI$15*Y38 -> 0 | AJ38: =$AJ$15*Y38 -> 0 | AK38: =$AK$15*Y38 -> 0 | AL38: =$AL$15*Y38 -> 0 | AM38: =$AM$15*Y38 -> 0 | AN38: =$AN$15*Y38 -> 0 | AO38: =$AO$15*Y38 -> 0 | AP38: =SUM(AC38:AO38) -> 0 | AR38: =IF(AC38=0,0,((F38*AC38)-($Y$4*$Y$5*AC38)-Y$7*AC38)/1.21) -> 0 | AS38: =IF(AD38=0,0,((G38*AD38)-($Y$4*$Y$5*AD38)-Z$7*AD38)/1.21) -> 0 | AT38: =IF(AE38=0,0,((H38*AE38)-($Y$4*$Y$5*AE38)-AA$7*AE38)/1.21) -> 0 | AU38: =IF(AF38=0,0,((I38*AF38)-($Y$4*$Y$5*AF38)-AB$7*AF38)/1.21) -> 0 | AV38: =IF(AG38=0,0,((J38*AG38)-($Y$4*$Y$5*AG38)-AC$7*AG38)/1.21) -> 0 | AW38: =IF(AH38=0,0,((K38*AH38)-($Y$4*$Y$5*AH38)-AD$7*AH38)/1.21) -> 0 | AX38: =IF(AI38=0,0,((L38*AI38)-($Y$4*$Y$5*AI38)-AE$7*AI38)/1.21) -> 0 | AY38: =IF(AJ38=0,0,((M38*AJ38)-($Y$4*$Y$5*AJ38)-AF$7*AJ38)/1.21) -> 0 | AZ38: =IF(AK38=0,0,((O38*AK38)-($Z$4*$Z$5*AK38)-AD32*AK38)/1.21) -> 0 | BA38: =IF(AL38=0,0,((N38*AL38)-($Y$4*$Y$5*AL38)-AH$7*AL38)/1.21) -> 0 | BB38: =IF(AM38=0,0,((P38*AM38)-($Y$4*$Y$5*AM38)-AI$7*AM38)/1.21) -> 0 | BC38: =IF(AN38=0,0,((Q38*AN38)-($Y$4*$Y$5*AN38)-AJ$7*AN38)/1.21) -> 0 | BD38: =IF(AO38=0,0,((R38*AO38)-($Y$4*$Y$5*AO38)-AK$7*AO38)/1.21) -> 0 | BE38: =SUM(AR38:BD38) -> 0
B39: Corporate Promotion 1 | F39: 0 | G39: =IF(F39=0,0,F39+$G$15) -> 0 | H39: =IF(F39=0,0,F39+$H$15) -> 0 | I39: =IF(F39=0,0,F39+$I$15) -> 0 | J39: =F39+$J$15 -> 0 | K39: =F39+$K$15 -> 0 | L39: =F39+$L$15 -> 0 | M39: =G39+$L$15 -> 0 | N39: =I39+$L$15 -> 0 | O39: =H39+$L$15 -> 0 | P39: =J39+$L$15 -> 0 | Q39: =K39+$L$15 -> 0 | R39: =L39+$L$15 -> 0 | Y39: 0 | AC39: =$AC$15*Y39 -> 0 | AD39: =$AD$15*Y39 -> 0 | AE39: =$AE$15*Y39 -> 0 | AF39: =$AF$15*Y39 -> 0 | AG39: =$AG$15*Y39 -> 0 | AH39: =$AH$15*Y39 -> 0 | AI39: =$AI$15*Y39 -> 0 | AJ39: =$AJ$15*Y39 -> 0 | AK39: =$AK$15*Y39 -> 0 | AL39: =$AL$15*Y39 -> 0 | AM39: =$AM$15*Y39 -> 0 | AN39: =$AN$15*Y39 -> 0 | AO39: =$AO$15*Y39 -> 0 | AP39: =SUM(AC39:AO39) -> 0 | AR39: =IF(AC39=0,0,((F39*AC39)-($Y$4*$Y$5*AC39)-Y$7*AC39)/1.21) -> 0 | AS39: =IF(AD39=0,0,((G39*AD39)-($Y$4*$Y$5*AD39)-Z$7*AD39)/1.21) -> 0 | AT39: =IF(AE39=0,0,((H39*AE39)-($Y$4*$Y$5*AE39)-AA$7*AE39)/1.21) -> 0 | AU39: =IF(AF39=0,0,((I39*AF39)-($Y$4*$Y$5*AF39)-AB$7*AF39)/1.21) -> 0 | AV39: =IF(AG39=0,0,((J39*AG39)-($Y$4*$Y$5*AG39)-AC$7*AG39)/1.21) -> 0 | AW39: =IF(AH39=0,0,((K39*AH39)-($Y$4*$Y$5*AH39)-AD$7*AH39)/1.21) -> 0 | AX39: =IF(AI39=0,0,((L39*AI39)-($Y$4*$Y$5*AI39)-AE$7*AI39)/1.21) -> 0 | AY39: =IF(AJ39=0,0,((M39*AJ39)-($Y$4*$Y$5*AJ39)-AF$7*AJ39)/1.21) -> 0 | AZ39: =IF(AK39=0,0,((O39*AK39)-($Z$4*$Z$5*AK39)-AD33*AK39)/1.21) -> 0 | BA39: =IF(AL39=0,0,((N39*AL39)-($Y$4*$Y$5*AL39)-AH$7*AL39)/1.21) -> 0 | BB39: =IF(AM39=0,0,((P39*AM39)-($Y$4*$Y$5*AM39)-AI$7*AM39)/1.21) -> 0 | BC39: =IF(AN39=0,0,((Q39*AN39)-($Y$4*$Y$5*AN39)-AJ$7*AN39)/1.21) -> 0 | BD39: =IF(AO39=0,0,((R39*AO39)-($Y$4*$Y$5*AO39)-AK$7*AO39)/1.21) -> 0 | BE39: =SUM(AR39:BD39) -> 0
B40: Corporate Promotion 2 | F40: 0 | G40: =IF(F40=0,0,F40+$G$15) -> 0 | H40: =IF(F40=0,0,F40+$H$15) -> 0 | I40: =IF(F40=0,0,F40+$I$15) -> 0 | J40: =F40+$J$15 -> 0 | K40: =F40+$K$15 -> 0 | L40: =F40+$L$15 -> 0 | M40: =G40+$L$15 -> 0 | N40: =I40+$L$15 -> 0 | O40: =H40+$L$15 -> 0 | P40: =J40+$L$15 -> 0 | Q40: =K40+$L$15 -> 0 | R40: =L40+$L$15 -> 0 | Y40: 0 | AC40: =$AC$15*Y40 -> 0 | AD40: =$AD$15*Y40 -> 0 | AE40: =$AE$15*Y40 -> 0 | AF40: =$AF$15*Y40 -> 0 | AG40: =$AG$15*Y40 -> 0 | AH40: =$AH$15*Y40 -> 0 | AI40: =$AI$15*Y40 -> 0 | AJ40: =$AJ$15*Y40 -> 0 | AK40: =$AK$15*Y40 -> 0 | AL40: =$AL$15*Y40 -> 0 | AM40: =$AM$15*Y40 -> 0 | AN40: =$AN$15*Y40 -> 0 | AO40: =$AO$15*Y40 -> 0 | AP40: =SUM(AC40:AO40) -> 0 | AR40: =IF(AC40=0,0,((F40*AC40)-($Y$4*$Y$5*AC40)-Y$7*AC40)/1.21) -> 0 | AS40: =IF(AD40=0,0,((G40*AD40)-($Y$4*$Y$5*AD40)-Z$7*AD40)/1.21) -> 0 | AT40: =IF(AE40=0,0,((H40*AE40)-($Y$4*$Y$5*AE40)-AA$7*AE40)/1.21) -> 0 | AU40: =IF(AF40=0,0,((I40*AF40)-($Y$4*$Y$5*AF40)-AB$7*AF40)/1.21) -> 0 | AV40: =IF(AG40=0,0,((J40*AG40)-($Y$4*$Y$5*AG40)-AC$7*AG40)/1.21) -> 0 | AW40: =IF(AH40=0,0,((K40*AH40)-($Y$4*$Y$5*AH40)-AD$7*AH40)/1.21) -> 0 | AX40: =IF(AI40=0,0,((L40*AI40)-($Y$4*$Y$5*AI40)-AE$7*AI40)/1.21) -> 0 | AY40: =IF(AJ40=0,0,((M40*AJ40)-($Y$4*$Y$5*AJ40)-AF$7*AJ40)/1.21) -> 0 | AZ40: =IF(AK40=0,0,((O40*AK40)-($Z$4*$Z$5*AK40)-AD34*AK40)/1.21) -> 0 | BA40: =IF(AL40=0,0,((N40*AL40)-($Y$4*$Y$5*AL40)-AH$7*AL40)/1.21) -> 0 | BB40: =IF(AM40=0,0,((P40*AM40)-($Y$4*$Y$5*AM40)-AI$7*AM40)/1.21) -> 0 | BC40: =IF(AN40=0,0,((Q40*AN40)-($Y$4*$Y$5*AN40)-AJ$7*AN40)/1.21) -> 0 | BD40: =IF(AO40=0,0,((R40*AO40)-($Y$4*$Y$5*AO40)-AK$7*AO40)/1.21) -> 0 | BE40: =SUM(AR40:BD40) -> 0
B41: Government New | F41: =F32 -> 2150000 | G41: =G32 -> 2350000 | H41: =H32 -> 2450000 | I41: =I32 -> 3050000 | J41: =J32 -> 3700000 | K41: =K32 -> 4800000 | L41: =L32 -> 5150000 | M41: =M32 -> 6400000 | ... R41: =R32 -> 30200000 | X41: =SUM(Y41:Y48) -> 0.022 | Y41: 0 | Z41: 0.022591788 | AA41: 0.069597219 | AC41: =$AC$15*Y41 -> 0 | AD41: =$AD$15*Y41 -> 0 | AE41: =$AE$15*Y41 -> 0 | AF41: =$AF$15*Y41 -> 0 | AG41: =$AG$15*Y41 -> 0 | AH41: =$AH$15*Y41 -> 0 | AI41: =$AI$15*Y41 -> 0 | AJ41: =$AJ$15*Y41 -> 0 | AK41: =$AK$15*Y41 -> 0 | AL41: =$AL$15*Y41 -> 0 | AM41: =$AM$15*Y41 -> 0 | AN41: =$AN$15*Y41 -> 0 | AO41: =$AO$15*Y41 -> 0 | AP41: =SUM(AC41:AO41) -> 0 | AR41: =IF(AC41=0,0,((F41*AC41)-($Y$4*$Y$5*AC41)-Y$7*AC41)/1.21) -> 0 | AS41: =IF(AD41=0,0,((G41*AD41)-($Y$4*$Y$5*AD41)-Z$7*AD41)/1.21) -> 0 | AT41: =IF(AE41=0,0,((H41*AE41)-($Y$4*$Y$5*AE41)-AA$7*AE41)/1.21) -> 0 | AU41: =IF(AF41=0,0,((I41*AF41)-($Y$4*$Y$5*AF41)-AB$7*AF41)/1.21) -> 0 | AV41: =IF(AG41=0,0,((J41*AG41)-($Y$4*$Y$5*AG41)-AC$7*AG41)/1.21) -> 0 | AW41: =IF(AH41=0,0,((K41*AH41)-($Y$4*$Y$5*AH41)-AD$7*AH41)/1.21) -> 0 | AX41: =IF(AI41=0,0,((L41*AI41)-($Y$4*$Y$5*AI41)-AE$7*AI41)/1.21) -> 0 | AY41: =IF(AJ41=0,0,((M41*AJ41)-($Y$4*$Y$5*AJ41)-AF$7*AJ41)/1.21) -> 0 | AZ41: =IF(AK41=0,0,((O41*AK41)-($Z$4*$Z$5*AK41)-#REF!*AK41)/1.21) -> 0 | BA41: =IF(AL41=0,0,((N41*AL41)-($Y$4*$Y$5*AL41)-AH$7*AL41)/1.21) -> 0 | BB41: =IF(AM41=0,0,((P41*AM41)-($Y$4*$Y$5*AM41)-AI$7*AM41)/1.21) -> 0 | BC41: =IF(AN41=0,0,((Q41*AN41)-($Y$4*$Y$5*AN41)-AJ$7*AN41)/1.21) -> 0 | BD41: =IF(AO41=0,0,((R41*AO41)-($Y$4*$Y$5*AO41)-AK$7*AO41)/1.21) -> 0 | BE41: =SUM(AR41:BD41) -> 0 | BF41: =SUM(BE41:BE48) -> 4.2014422e+09 | BG41: Govt | BH41: 4907992472
...

Sheet Sheet2
D11: Deluxe Room | E11: 2600000 | F11: 2900000 | G11: 3200000 | H11: 3400000
D12: Deluxe Pool Access | E12: 2800000 | F12: 3100000 | G12: 3400000 | H12: 3600000
D13: Premiere Room | E13: 2900000 | F13: 3200000 | G13: 3500000 | H13: 3700000
D14: Premiere Lagoon Access | E14: 3500000 | F14: 3800000 | G14: 4100000 | H14: 4300000
D15: Family Premiere | E15: 4150000 | F15: 4450000 | G15: 4750000 | H15: 4950000
D16: Deluxe Suite | E16: 5100000 | F16: 5400000 | G16: 5700000 | H16: 5900000
D17: Premiere Suite | E17: 5550000 | F17: 5850000 | G17: 6150000 | H17: 6350000
D18: The Anvaya Suite No Pool | E18: 6800000 | F18: 7100000 | G18: 7400000 | H18: 7600000
D19: The Anvaya Suite Whirl Pool | E19: 7350000 | F19: 7650000 | G19: 7950000 | H19: 8150000
D20: Beach Front Private Suite | E20: 7600000 | F20: 7900000 | G20: 8200000 | H20: 8400000
D21: Anvaya Residence | E21: 11000000 | F21: 11300000 | G21: 11600000 | H21: 11800000
D22: The Anvaya Suite with Pool | E22: 9450000 | F22: 9750000 | G22: 10050000 | H22: 10250000
D23: The Anvaya Villa | E23: 29650000 | F23: 29950000 | G23: 30250000 | H23: 30450000

Sheet tactical
B2: OTA Comission | D2: 0.16
A6: Room Type | B6: BAR - OTA | C6: OTA GEO | D6: OTA Net | E6: OTA GEO NET | F6: Wholesale Margin | G6: Wholesale Net | H6: Wholesaler Retail | I6: Parity Diff | J6: Parity Status | K6: Corporate | L6: WW | M6: margin Bedbanks | N6: Net to Bedbanks | O6: Hotelbeds - Differential
A7: Deluxe Room | B7: ='7. Rate Strategy'!F$28 -> 2431000 | C7: =B7-(B7*10%) -> 2187900 | D7: =B7*(1-$D$2) -> 2042040 | E7: =C7*(1-$D$2) -> 1837836 | F7: 0.15 | G7: =MROUND(B7*(1-F7),50000) -> 2050000 | H7: =G7*(1+F7) -> 2357500 | I7: =(B7-H7)/B7 -> 0.030234471 | J7: =IF(I7<=0.03,"✅","⚠️") -> ⚠️ | K7: 2150000 | L7: 2600000 | M7: 0.15 | N7: =FLOOR(B7*(1-M7),50000) -> 2050000 | O7: 0.05 | P7: =FLOOR(N7-(N7*O7),5000) -> 1945000 | Q7: =(P7-N7)/N7 -> -0.051219512
A8: Deluxe Pool Access | B8: ='7. Rate Strategy'!G$28 -> 2618000 | C8: =B8-(B8*10%) -> 2356200 | D8: =B8*(1-$D$2) -> 2199120 | E8: =C8*(1-$D$2) -> 1979208 | F8: 0.15 | G8: =MROUND(B8*(1-F8),50000) -> 2250000 | H8: =G8*(1+F8) -> 2587500 | I8: =(B8-H8)/B8 -> 0.011650115 | J8: =IF(I8<=0.03,"✅","⚠️") -> ✅ | K8: 2350000 | L8: 2800000 | M8: 0.15 | N8: =FLOOR(B8*(1-M8),50000) -> 2200000 | O8: 0.05 | P8: =FLOOR(N8-(N8*O8),5000) -> 2090000 | Q8: =(P8-N8)/N8 -> -0.05
